Workbook

Sheet Checklist
A1: Pillar7 | B1: Function | C1: SubFunction | D1: Spec | E1: Stage | F1: Requirement | G1: Answer | H1: Score
A2: 신원 | B2: 식별자 관리 | C2: 사용자 인벤토리 | D2: 사용자 인벤토리는 시스템에 접근하는 모든 사용자와 그들의 권한을 기록하고 관리하는 시스템이다. 이 기능은 사용자에 대한 정확하고 최신 정보를 제공하여 적절한 접근 제어를 가능하게 한다. | E2: 초기 | F2: - 사용자의 역할 및 권한을 포함한 상세 인벤토리 구축하고 있는가? | G2: Y | H2: =IF(G2="Y",1,IF(G2="N",0,"")) -> 1
A3: 신원 | B3: 식별자 관리 | C3: 사용자 인벤토리 | D3: 사용자 인벤토리는 시스템에 접근하는 모든 사용자와 그들의 권한을 기록하고 관리하는 시스템이다. 이 기능은 사용자에 대한 정확하고 최신 정보를 제공하여 적절한 접근 제어를 가능하게 한다. | E3: 초기 | F3: - 주기적인 검토와 업데이트 절차 설정하고 있는가? | G3: Y | H3: =IF(G3="Y",1,IF(G3="N",0,"")) -> 1
A4: 신원 | B4: 식별자 관리 | C4: 사용자 인벤토리 | D4: 사용자 인벤토리는 시스템에 접근하는 모든 사용자와 그들의 권한을 기록하고 관리하는 시스템이다. 이 기능은 사용자에 대한 정확하고 최신 정보를 제공하여 적절한 접근 제어를 가능하게 한다. | E4: 향상 | F4: - 자동화된 인벤토리 관리 도구 도입을 통한 사용자 데이터 정확성 보장하고 있는가? | G4: N | H4: =IF(G4="Y",1,IF(G4="N",0,"")) -> 0
A5: 신원 | B5: 식별자 관리 | C5: 사용자 인벤토리 | D5: 사용자 인벤토리는 시스템에 접근하는 모든 사용자와 그들의 권한을 기록하고 관리하는 시스템이다. 이 기능은 사용자에 대한 정확하고 최신 정보를 제공하여 적절한 접근 제어를 가능하게 한다. | E5: 향상 | F5: - ID 통합 관리 시스템을 구축하고 있는가? | G5: N | H5: =IF(G5="Y",1,IF(G5="N",0,"")) -> 0
A6: 신원 | B6: 식별자 관리 | C6: 사용자 인벤토리 | D6: 사용자 인벤토리는 시스템에 접근하는 모든 사용자와 그들의 권한을 기록하고 관리하는 시스템이다. 이 기능은 사용자에 대한 정확하고 최신 정보를 제공하여 적절한 접근 제어를 가능하게 한다. | E6: 향상 | F6: - 비정상적인 사용자 활동 탐지 기능 추가하고 있는가? | G6: N | H6: =IF(G6="Y",1,IF(G6="N",0,"")) -> 0
A7: 신원 | B7: 식별자 관리 | C7: 사용자 인벤토리 | D7: 사용자 인벤토리는 시스템에 접근하는 모든 사용자와 그들의 권한을 기록하고 관리하는 시스템이다. 이 기능은 사용자에 대한 정확하고 최신 정보를 제공하여 적절한 접근 제어를 가능하게 한다. | E7: 최적화 | F7: - 인벤토리 통합을 통한 기업 전반의 사용자 및 권한 관리 최적화하고 있는가? | G7: N | H7: =IF(G7="Y",1,IF(G7="N",0,"")) -> 0
A8: 신원 | B8: 식별자 관리 | C8: 사용자 인벤토리 | D8: 사용자 인벤토리는 시스템에 접근하는 모든 사용자와 그들의 권한을 기록하고 관리하는 시스템이다. 이 기능은 사용자에 대한 정확하고 최신 정보를 제공하여 적절한 접근 제어를 가능하게 한다. | E8: 최적화 | F8: - 인공지능 기반 분석을 수행하여 사용자 행동 예측 및 대응 전략 걍화하고 있는가? | G8: N | H8: =IF(G8="Y",1,IF(G8="N",0,"")) -> 0
A9: 신원 | B9: 식별자 관리 | C9: ID 연계 및 사용자 자격 증명 | D9: 여러 시스템 간의 사용자 자격 증명과 인증을 통합하는 프로세스로, 처음에는 ID 생명주기 관리 프로세스를 표준화하고, 표준 조직 IDP 솔루션과 통합하는 데 초점을 맞춘다. 이를 완료한 후, 단일 솔루션이나 ID 연계를 통해 기업용 ILM 프로세스·솔루션을 구축하는 것으로 전환된다. | E9: 초기 | F9: - 여러 시스템 간 자격 증명 연동으로 사용자 경험 통합하고 있는가? | G9: N | H9: =IF(G9="Y",1,IF(G9="N",0,"")) -> 0
A10: 신원 | B10: 식별자 관리 | C10: ID 연계 및 사용자 자격 증명 | D10: 여러 시스템 간의 사용자 자격 증명과 인증을 통합하는 프로세스로, 처음에는 ID 생명주기 관리 프로세스를 표준화하고, 표준 조직 IDP 솔루션과 통합하는 데 초점을 맞춘다. 이를 완료한 후, 단일 솔루션이나 ID 연계를 통해 기업용 ILM 프로세스·솔루션을 구축하는 것으로 전환된다. | E10: 초기 | F10: - 기업 내외부 시스템과의 연동 강화하고 있는가? | G10: N | H10: =IF(G10="Y",1,IF(G10="N",0,"")) -> 0
A11: 신원 | B11: 식별자 관리 | C11: ID 연계 및 사용자 자격 증명 | D11: 여러 시스템 간의 사용자 자격 증명과 인증을 통합하는 프로세스로, 처음에는 ID 생명주기 관리 프로세스를 표준화하고, 표준 조직 IDP 솔루션과 통합하는 데 초점을 맞춘다. 이를 완료한 후, 단일 솔루션이나 ID 연계를 통해 기업용 ILM 프로세스·솔루션을 구축하는 것으로 전환된다. | E11: 향상 | F11: - 다양한 ID 제공자 통합을 통한 ID 연계 확대하고 있는가? | G11: N | H11: =IF(G11="Y",1,IF(G11="N",0,"")) -> 0
A12: 신원 | B12: 식별자 관리 | C12: ID 연계 및 사용자 자격 증명 | D12: 여러 시스템 간의 사용자 자격 증명과 인증을 통합하는 프로세스로, 처음에는 ID 생명주기 관리 프로세스를 표준화하고, 표준 조직 IDP 솔루션과 통합하는 데 초점을 맞춘다. 이를 완료한 후, 단일 솔루션이나 ID 연계를 통해 기업용 ILM 프로세스·솔루션을 구축하는 것으로 전환된다. | E12: 향상 | F12: - 보안 프로토콜 강화로 데이터 보호 개선하고 있는가? | G12: N | H12: =IF(G12="Y",1,IF(G12="N",0,"")) -> 0
A13: 신원 | B13: 식별자 관리 | C13: ID 연계 및 사용자 자격 증명 | D13: 여러 시스템 간의 사용자 자격 증명과 인증을 통합하는 프로세스로, 처음에는 ID 생명주기 관리 프로세스를 표준화하고, 표준 조직 IDP 솔루션과 통합하는 데 초점을 맞춘다. 이를 완료한 후, 단일 솔루션이나 ID 연계를 통해 기업용 ILM 프로세스·솔루션을 구축하는 것으로 전환된다. | E13: 최적화 | F13: - 글로벌 수준의 ID 연계 구현을 통한 통합 사용자 경험 제공하고 있는가? | G13: N | H13: =IF(G13="Y",1,IF(G13="N",0,"")) -> 0
... A278: 데이터 | B278: 데이터 손실 방지 | C278: 데이터 모니터링 및 감지 | D278: 데이터 사용과 이동을 실시간으로 모니터링하고, 비정상적인 활동을 탐지하여 데이터 유출을 사전에 방지한다. | E278: 최적화 | F278: - 모든 데이터 활동 지속적 평가 및 자동화된 보안 대응 시스템 구현하고 있는가? | G278: Y | H278: =IF(G278="Y",1,IF(G278="N",0,"")) -> 1
A279: 가시성 및 분석 | C279: 모든 관련 활동 기록 | D279: 네트워크, 사용자, 기기, 애플리케이션 등에서 발생하는 모든 이벤트를 기록하여 저장하는 기능이다. 이를 로그 데이터를 생성하고 이를 기반으로 하여 분석을 위한 데이터를 축적하는 역할을 한다. 또한 활동에는 로그인 시도, 접근권한 변경, 데이터 접근, 애플리케이션 실행 등 보안과 관련된 모든 활동이 포함된다. 이 기능은 잠재적인 보안 위협을 식별하고, 사건 발생 시 원인을 추적하여 분석을 가능하게 한다. | E279: 초기 | F279: - 다양한 시스템에서 자동으로 로그 데이터 수집하고 있는가? | G279: Y | H279: =IF(G279="Y",1,IF(G279="N",0,"")) -> 1
A280: 가시성 및 분석 | C280: 모든 관련 활동 기록 | D280: 네트워크, 사용자, 기기, 애플리케이션 등에서 발생하는 모든 이벤트를 기록하여 저장하는 기능이다. 이를 로그 데이터를 생성하고 이를 기반으로 하여 분석을 위한 데이터를 축적하는 역할을 한다. 또한 활동에는 로그인 시도, 접근권한 변경, 데이터 접근, 애플리케이션 실행 등 보안과 관련된 모든 활동이 포함된다. 이 기능은 잠재적인 보안 위협을 식별하고, 사건 발생 시 원인을 추적하여 분석을 가능하게 한다. | E280: 초기 | F280: - 활동 기록 중앙집중화 수립하고 있는가? | G280: Y | H280: =IF(G280="Y",1,IF(G280="N",0,"")) -> 1
A281: 가시성 및 분석 | C281: 모든 관련 활동 기록 | D281: 네트워크, 사용자, 기기, 애플리케이션 등에서 발생하는 모든 이벤트를 기록하여 저장하는 기능이다. 이를 로그 데이터를 생성하고 이를 기반으로 하여 분석을 위한 데이터를 축적하는 역할을 한다. 또한 활동에는 로그인 시도, 접근권한 변경, 데이터 접근, 애플리케이션 실행 등 보안과 관련된 모든 활동이 포함된다. 이 기능은 잠재적인 보안 위협을 식별하고, 사건 발생 시 원인을 추적하여 분석을 가능하게 한다. | E281: 초기 | F281: - 로그 수집은 네트워크, 애플리케이션, 기기 등 여러 곳에서 이루어지며, 실시간으로 보안 이벤트 기록하고 있는가? | G281: Y | H281: =IF(G281="Y",1,IF(G281="N",0,"")) -> 1
A282: 가시성 및 분석 | C282: 모든 관련 활동 기록 | D282: 네트워크, 사용자, 기기, 애플리케이션 등에서 발생하는 모든 이벤트를 기록하여 저장하는 기능이다. 이를 로그 데이터를 생성하고 이를 기반으로 하여 분석을 위한 데이터를 축적하는 역할을 한다. 또한 활동에는 로그인 시도, 접근권한 변경, 데이터 접근, 애플리케이션 실행 등 보안과 관련된 모든 활동이 포함된다. 이 기능은 잠재적인 보안 위협을 식별하고, 사건 발생 시 원인을 추적하여 분석을 가능하게 한다. | E282: 초기 | F282: - 로그 수집 및 관리 자동화하고 있는가? | G282: Y | H282: =IF(G282="Y",1,IF(G282="N",0,"")) -> 1
A283: 가시성 및 분석 | C283: 모든 관련 활동 기록 | D283: 네트워크, 사용자, 기기, 애플리케이션 등에서 발생하는 모든 이벤트를 기록하여 저장하는 기능이다. 이를 로그 데이터를 생성하고 이를 기반으로 하여 분석을 위한 데이터를 축적하는 역할을 한다. 또한 활동에는 로그인 시도, 접근권한 변경, 데이터 접근, 애플리케이션 실행 등 보안과 관련된 모든 활동이 포함된다. 이 기능은 잠재적인 보안 위협을 식별하고, 사건 발생 시 원인을 추적하여 분석을 가능하게 한다. | E283: 초기 | F283: - 보안 사고 발생 시 신속하게 로그를 분석하고 대응할 수 있는 기반 마련하고 있는가? | G283: Y | H283: =IF(G283="Y",1,IF(G283="N",0,"")) -> 1
A284: 가시성 및 분석 | C284: 모든 관련 활동 기록 | D284: 네트워크, 사용자, 기기, 애플리케이션 등에서 발생하는 모든 이벤트를 기록하여 저장하는 기능이다. 이를 로그 데이터를 생성하고 이를 기반으로 하여 분석을 위한 데이터를 축적하는 역할을 한다. 또한 활동에는 로그인 시도, 접근권한 변경, 데이터 접근, 애플리케이션 실행 등 보안과 관련된 모든 활동이 포함된다. 이 기능은 잠재적인 보안 위협을 식별하고, 사건 발생 시 원인을 추적하여 분석을 가능하게 한다. | E284: 향상 | F284: - 수집된 데이터를 분석하여 보안 위협을 실시간으로 탐지하고 경고 생성하고 있는가? | G284: Y | H284: =IF(G284="Y",1,IF(G284="N",0,"")) -> 1
A285: 가시성 및 분석 | C285: 모든 관련 활동 기록 | D285: 네트워크, 사용자, 기기, 애플리케이션 등에서 발생하는 모든 이벤트를 기록하여 저장하는 기능이다. 이를 로그 데이터를 생성하고 이를 기반으로 하여 분석을 위한 데이터를 축적하는 역할을 한다. 또한 활동에는 로그인 시도, 접근권한 변경, 데이터 접근, 애플리케이션 실행 등 보안과 관련된 모든 활동이 포함된다. 이 기능은 잠재적인 보안 위협을 식별하고, 사건 발생 시 원인을 추적하여 분석을 가능하게 한다. | E285: 향상 | F285: - 로그 기록의 무결성 보장하고 있는가? | G285: Y | H285: =IF(G285="Y",1,IF(G285="N",0,"")) -> 1
A286: 가시성 및 분석 | C286: 모든 관련 활동 기록 | D286: 네트워크, 사용자, 기기, 애플리케이션 등에서 발생하는 모든 이벤트를 기록하여 저장하는 기능이다. 이를 로그 데이터를 생성하고 이를 기반으로 하여 분석을 위한 데이터를 축적하는 역할을 한다. 또한 활동에는 로그인 시도, 접근권한 변경, 데이터 접근, 애플리케이션 실행 등 보안과 관련된 모든 활동이 포함된다. 이 기능은 잠재적인 보안 위협을 식별하고, 사건 발생 시 원인을 추적하여 분석을 가능하게 한다. | E286: 향상 | F286: - 로그 데이터를 기반으로 예측 분석 시작하고 있는가? | G286: Y | H286: =IF(G286="Y",1,IF(G286="N",0,"")) -> 1
A287: 가시성 및 분석 | C287: 모든 관련 활동 기록 | D287: 네트워크, 사용자, 기기, 애플리케이션 등에서 발생하는 모든 이벤트를 기록하여 저장하는 기능이다. 이를 로그 데이터를 생성하고 이를 기반으로 하여 분석을 위한 데이터를 축적하는 역할을 한다. 또한 활동에는 로그인 시도, 접근권한 변경, 데이터 접근, 애플리케이션 실행 등 보안과 관련된 모든 활동이 포함된다. 이 기능은 잠재적인 보안 위협을 식별하고, 사건 발생 시 원인을 추적하여 분석을 가능하게 한다. | E287: 향상 | F287: - 비정상적인 활동 사전 감지하고 있는가? | G287: Y | H287: =IF(G287="Y",1,IF(G287="N",0,"")) -> 1
A288: 가시성 및 분석 | C288: 모든 관련 활동 기록 | D288: 네트워크, 사용자, 기기, 애플리케이션 등에서 발생하는 모든 이벤트를 기록하여 저장하는 기능이다. 이를 로그 데이터를 생성하고 이를 기반으로 하여 분석을 위한 데이터를 축적하는 역할을 한다. 또한 활동에는 로그인 시도, 접근권한 변경, 데이터 접근, 애플리케이션 실행 등 보안과 관련된 모든 활동이 포함된다. 이 기능은 잠재적인 보안 위협을 식별하고, 사건 발생 시 원인을 추적하여 분석을 가능하게 한다. | E288: 최적화 | F288: - AI를 활용한 로그 분석 시스템 구축하고 있는가? | G288: Y | H288: =IF(G288="Y",1,IF(G288="N",0,"")) -> 1
A289: 가시성 및 분석 | C289: 모든 관련 활동 기록 | D289: 네트워크, 사용자, 기기, 애플리케이션 등에서 발생하는 모든 이벤트를 기록하여 저장하는 기능이다. 이를 로그 데이터를 생성하고 이를 기반으로 하여 분석을 위한 데이터를 축적하는 역할을 한다. 또한 활동에는 로그인 시도, 접근권한 변경, 데이터 접근, 애플리케이션 실행 등 보안과 관련된 모든 활동이 포함된다. 이 기능은 잠재적인 보안 위협을 식별하고, 사건 발생 시 원인을 추적하여 분석을 가능하게 한다. | E289: 최적화 | F289: - 실시간으로 활동 기록 분석 및 자동으로 보안 위협에 대응하는 자율 보안 체계 구현하고 있는가? | G289: Y | H289: =IF(G289="Y",1,IF(G289="N",0,"")) -> 1
A290: 가시성 및 분석 | C290: 모든 관련 활동 기록 | D290: 네트워크, 사용자, 기기, 애플리케이션 등에서 발생하는 모든 이벤트를 기록하여 저장하는 기능이다. 이를 로그 데이터를 생성하고 이를 기반으로 하여 분석을 위한 데이터를 축적하는 역할을 한다. 또한 활동에는 로그인 시도, 접근권한 변경, 데이터 접근, 애플리케이션 실행 등 보안과 관련된 모든 활동이 포함된다. 이 기능은 잠재적인 보안 위협을 식별하고, 사건 발생 시 원인을 추적하여 분석을 가능하게 한다. | E290: 최적화 | F290: - 로그 데이터 관련 항목 분석 자동화 및 정규화하고 있는가? | G290: Y | H290: =IF(G290="Y",1,IF(G290="N",0,"")) -> 1
... A395: 자동화 및 통합 | C395: 보안 운영 조정 및 사고 대응 | D395: 기업 내 보안 사고가 발생했을 때, 이를 신속하게 대응하고 기업 내 여러 부서가 조정하여 보안 문제를 해결하는 과정이다. 이를 통해 사고가 발생하더라도 피해를 최소화할 수 있다. | E395: 최적화 | F395: - 대응 결과 즉시 보고하고 있는가? | G395: Y | H395: =IF(G395="Y",1,IF(G395="N",0,"")) -> 1

Sheet SubFunctionSummary
A1: Pillar7 | B1: Function | C1: SubFunction | D1: Init_N | E1: Imp_Y | F1: Imp_Total | G1: Opt_Y | H1: Opt_Total | I1: SubFuncScore
A2: 신원 | B2: 식별자 관리 | C2: 사용자 인벤토리 | D2: =IF($B2="",COUNTIFS(Checklist!$A:$A,$A2,Checklist!$C:$C,$C2,Checklist!$E:$E,"초기",Checklist!$G:$G,"N"),COUNTIFS(Checklist!$A:$A,$A2,Checklist!$B:$B,$B2,Checklist!$C:$C,$C2,Checklist!$E:$E,"초기",Checklist!$G:$G,"N")) -> 0 | E2: =IF($B2="",COUNTIFS(Checklist!$A:$A,$A2,Checklist!$C:$C,$C2,Checklist!$E:$E,"향상",Checklist!$G:$G,"Y"),COUNTIFS(Checklist!$A:$A,$A2,Checklist!$B:$B,$B2,Checklist!$C:$C,$C2,Checklist!$E:$E,"향상",Checklist!$G:$G,"Y")) -> 0 | F2: =IF($B2="",COUNTIFS(Checklist!$A:$A,$A2,Checklist!$C:$C,$C2,Checklist!$E:$E,"향상",Checklist!$H:$H,"<>"),COUNTIFS(Checklist!$A:$A,$A2,Checklist!$B:$B,$B2,Checklist!$C:$C,$C2,Checklist!$E:$E,"향상",Checklist!$H:$H,"<>")) -> 3 | G2: =IF($B2="",COUNTIFS(Checklist!$A:$A,$A2,Checklist!$C:$C,$C2,Checklist!$E:$E,"최적화",Checklist!$G:$G,"Y"),COUNTIFS(Checklist!$A:$A,$A2,Checklist!$B:$B,$B2,Checklist!$C:$C,$C2,Checklist!$E:$E,"최적화",Checklist!$G:$G,"Y")) -> 0 | H2: =IF($B2="",COUNTIFS(Checklist!$A:$A,$A2,Checklist!$C:$C,$C2,Checklist!$E:$E,"최적화",Checklist!$H:$H,"<>"),COUNTIFS(Checklist!$A:$A,$A2,Checklist!$B:$B,$B2,Checklist!$C:$C,$C2,Checklist!$E:$E,"최적화",Checklist!$H:$H,"<>")) -> 2 | I2: =IF(D2>0,0,IF(AND(F2=0,H2=0),0.4,IF(AND(F2>0,IF($B2="",COUNTIFS(Checklist!$A:$A,$A2,Checklist!$C:$C,$C2,Checklist!$E:$E,"향상",Checklist!$G:$G,"N"),COUNTIFS(Checklist!$A:$A,$A2,Checklist!$B:$B,$B2,Checklist!$C:$C,$C2,Checklist!$E:$E,"향상",Checklist!$G:$G,"N"))=0,H2>0,IF($B2="",COUNTIFS(Checklist!$A:$A,$A2,Checklist!$C:$C,$C2,Checklist!$E:$E,"최적화",Checklist!$G:$G,"N"),COUNTIFS(Checklist!$A:$A,$A2,Checklist!$B:$B,$B2,Checklist!$C:$C,$C2,Checklist!$E:$E,"최적화",Checklist!$G:$G,"N"))=0),0.7+0.3*IF(H2=0,0,G2/H2),0.4+0.3*IF(F2=0,0,E2/F2)))) -> 0.4
A3: 신원 | B3: 식별자 관리 | C3: ID 연계 및 사용자 자격 증명 | D3: =IF($B3="",COUNTIFS(Checklist!$A:$A,$A3,Checklist!$C:$C,$C3,Checklist!$E:$E,"초기",Checklist!$G:$G,"N"),COUNTIFS(Checklist!$A:$A,$A3,Checklist!$B:$B,$B3,Checklist!$C:$C,$C3,Checklist!$E:$E,"초기",Checklist!$G:$G,"N")) -> 2 | E3: =IF($B3="",COUNTIFS(Checklist!$A:$A,$A3,Checklist!$C:$C,$C3,Checklist!$E:$E,"향상",Checklist!$G:$G,"Y"),COUNTIFS(Checklist!$A:$A,$A3,Checklist!$B:$B,$B3,Checklist!$C:$C,$C3,Checklist!$E:$E,"향상",Checklist!$G:$G,"Y")) -> 0 | F3: =IF($B3="",COUNTIFS(Checklist!$A:$A,$A3,Checklist!$C:$C,$C3,Checklist!$E:$E,"향상",Checklist!$H:$H,"<>"),COUNTIFS(Checklist!$A:$A,$A3,Checklist!$B:$B,$B3,Checklist!$C:$C,$C3,Checklist!$E:$E,"향상",Checklist!$H:$H,"<>")) -> 2 | G3: =IF($B3="",COUNTIFS(Checklist!$A:$A,$A3,Checklist!$C:$C,$C3,Checklist!$E:$E,"최적화",Checklist!$G:$G,"Y"),COUNTIFS(Checklist!$A:$A,$A3,Checklist!$B:$B,$B3,Checklist!$C:$C,$C3,Checklist!$E:$E,"최적화",Checklist!$G:$G,"Y")) -> 0 | H3: =IF($B3="",COUNTIFS(Checklist!$A:$A,$A3,Checklist!$C:$C,$C3,Checklist!$E:$E,"최적화",Checklist!$H:$H,"<>"),COUNTIFS(Checklist!$A:$A,$A3,Checklist!$B:$B,$B3,Checklist!$C:$C,$C3,Checklist!$E:$E,"최적화",Checklist!$H:$H,"<>")) -> 2 | I3: =IF(D3>0,0,IF(AND(F3=0,H3=0),0.4,IF(AND(F3>0,IF($B3="",COUNTIFS(Checklist!$A:$A,$A3,Checklist!$C:$C,$C3,Checklist!$E:$E,"향상",Checklist!$G:$G,"N"),COUNTIFS(Checklist!$A:$A,$A3,Checklist!$B:$B,$B3,Checklist!$C:$C,$C3,Checklist!$E:$E,"향상",Checklist!$G:$G,"N"))=0,H3>0,IF($B3="",COUNTIFS(Checklist!$A:$A,$A3,Checklist!$C:$C,$C3,Checklist!$E:$E,"최적화",Checklist!$G:$G,"N"),COUNTIFS(Checklist!$A:$A,$A3,Checklist!$B:$B,$B3,Checklist!$C:$C,$C3,Checklist!$E:$E,"최적화",Checklist!$G:$G,"N"))=0),0.7+0.3*IF(H3=0,0,G3/H3),0.4+0.3*IF(F3=0,0,E3/F3)))) -> 0
A4: 신원 | B4: 인증 | C4: 다중인증(MFA) | D4: =IF($B4="",COUNTIFS(Checklist!$A:$A,$A4,Checklist!$C:$C,$C4,Checklist!$E:$E,"초기",Checklist!$G:$G,"N"),COUNTIFS(Checklist!$A:$A,$A4,Checklist!$B:$B,$B4,Checklist!$C:$C,$C4,Checklist!$E:$E,"초기",Checklist!$G:$G,"N")) -> 3 | E4: =IF($B4="",COUNTIFS(Checklist!$A:$A,$A4,Checklist!$C:$C,$C4,Checklist!$E:$E,"향상",Checklist!$G:$G,"Y"),COUNTIFS(Checklist!$A:$A,$A4,Checklist!$B:$B,$B4,Checklist!$C:$C,$C4,Checklist!$E:$E,"향상",Checklist!$G:$G,"Y")) -> 1 | F4: =IF($B4="",COUNTIFS(Checklist!$A:$A,$A4,Checklist!$C:$C,$C4,Checklist!$E:$E,"향상",Checklist!$H:$H,"<>"),COUNTIFS(Checklist!$A:$A,$A4,Checklist!$B:$B,$B4,Checklist!$C:$C,$C4,Checklist!$E:$E,"향상",Checklist!$H:$H,"<>")) -> 3 | G4: =IF($B4="",COUNTIFS(Checklist!$A:$A,$A4,Checklist!$C:$C,$C4,Checklist!$E:$E,"최적화",Checklist!$G:$G,"Y"),COUNTIFS(Checklist!$A:$A,$A4,Checklist!$B:$B,$B4,Checklist!$C:$C,$C4,Checklist!$E:$E,"최적화",Checklist!$G:$G,"Y")) -> 3 | H4: =IF($B4="",COUNTIFS(Checklist!$A:$A,$A4,Checklist!$C:$C,$C4,Checklist!$E:$E,"최적화",Checklist!$H:$H,"<>"),COUNTIFS(Checklist!$A:$A,$A4,Checklist!$B:$B,$B4,Checklist!$C:$C,$C4,Checklist!$E:$E,"최적화",Checklist!$H:$H,"<>")) -> 3 | I4: =IF(D4>0,0,IF(AND(F4=0,H4=0),0.4,IF(AND(F4>0,IF($B4="",COUNTIFS(Checklist!$A:$A,$A4,Checklist!$C:$C,$C4,Checklist!$E:$E,"향상",Checklist!$G:$G,"N"),COUNTIFS(Checklist!$A:$A,$A4,Checklist!$B:$B,$B4,Checklist!$C:$C,$C4,Checklist!$E:$E,"향상",Checklist!$G:$G,"N"))=0,H4>0,IF($B4="",COUNTIFS(Checklist!$A:$A,$A4,Checklist!$C:$C,$C4,Checklist!$E:$E,"최적화",Checklist!$G:$G,"N"),COUNTIFS(Checklist!$A:$A,$A4,Checklist!$B:$B,$B4,Checklist!$C:$C,$C4,Checklist!$E:$E,"최적화",Checklist!$G:$G,"N"))=0),0.7+0.3*IF(H4=0,0,G4/H4),0.4+0.3*IF(F4=0,0,E4/F4)))) -> 0
A5: 신원 | B5: 인증 | C5: 지속 인증 | D5: =IF($B5="",COUNTIFS(Checklist!$A:$A,$A5,Checklist!$C:$C,$C5,Checklist!$E:$E,"초기",Checklist!$G:$G,"N"),COUNTIFS(Checklist!$A:$A,$A5,Checklist!$B:$B,$B5,Checklist!$C:$C,$C5,Checklist!$E:$E,"초기",Checklist!$G:$G,"N")) -> 0 | E5: =IF($B5="",COUNTIFS(Checklist!$A:$A,$A5,Checklist!$C:$C,$C5,Checklist!$E:$E,"향상",Checklist!$G:$G,"Y"),COUNTIFS(Checklist!$A:$A,$A5,Checklist!$B:$B,$B5,Checklist!$C:$C,$C5,Checklist!$E:$E,"향상",Checklist!$G:$G,"Y")) -> 2 | F5: =IF($B5="",COUNTIFS(Checklist!$A:$A,$A5,Checklist!$C:$C,$C5,Checklist!$E:$E,"향상",Checklist!$H:$H,"<>"),COUNTIFS(Checklist!$A:$A,$A5,Checklist!$B:$B,$B5,Checklist!$C:$C,$C5,Checklist!$E:$E,"향상",Checklist!$H:$H,"<>")) -> 2 | G5: =IF($B5="",COUNTIFS(Checklist!$A:$A,$A5,Checklist!$C:$C,$C5,Checklist!$E:$E,"최적화",Checklist!$G:$G,"Y"),COUNTIFS(Checklist!$A:$A,$A5,Checklist!$B:$B,$B5,Checklist!$C:$C,$C5,Checklist!$E:$E,"최적화",Checklist!$G:$G,"Y")) -> 1 | H5: =IF($B5="",COUNTIFS(Checklist!$A:$A,$A5,Checklist!$C:$C,$C5,Checklist!$E:$E,"최적화",Checklist!$H:$H,"<>"),COUNTIFS(Checklist!$A:$A,$A5,Checklist!$B:$B,$B5,Checklist!$C:$C,$C5,Checklist!$E:$E,"최적화",Checklist!$H:$H,"<>")) -> 1 | I5: =IF(D5>0,0,IF(AND(F5=0,H5=0),0.4,IF(AND(F5>0,IF($B5="",COUNTIFS(Checklist!$A:$A,$A5,Checklist!$C:$C,$C5,Checklist!$E:$E,"향상",Checklist!$G:$G,"N"),COUNTIFS(Checklist!$A:$A,$A5,Checklist!$B:$B,$B5,Checklist!$C:$C,$C5,Checklist!$E:$E,"향상",Checklist!$G:$G,"N"))=0,H5>0,IF($B5="",COUNTIFS(Checklist!$A:$A,$A5,Checklist!$C:$C,$C5,Checklist!$E:$E,"최적화",Checklist!$G:$G,"N"),COUNTIFS(Checklist!$A:$A,$A5,Checklist!$B:$B,$B5,Checklist!$C:$C,$C5,Checklist!$E:$E,"최적화",Checklist!$G:$G,"N"))=0),0.7+0.3*IF(H5=0,0,G5/H5),0.4+0.3*IF(F5=0,0,E5/F5)))) -> 1
A6: 신원 | B6: 위험도 평가 | C6: 통합 ICAM 플랫폼 | D6: =IF($B6="",COUNTIFS(Checklist!$A:$A,$A6,Checklist!$C:$C,$C6,Checklist!$E:$E,"초기",Checklist!$G:$G,"N"),COUNTIFS(Checklist!$A:$A,$A6,Checklist!$B:$B,$B6,Checklist!$C:$C,$C6,Checklist!$E:$E,"초기",Checklist!$G:$G,"N")) -> 0 | E6: =IF($B6="",COUNTIFS(Checklist!$A:$A,$A6,Checklist!$C:$C,$C6,Checklist!$E:$E,"향상",Checklist!$G:$G,"Y"),COUNTIFS(Checklist!$A:$A,$A6,Checklist!$B:$B,$B6,Checklist!$C:$C,$C6,Checklist!$E:$E,"향상",Checklist!$G:$G,"Y")) -> 3 | F6: =IF($B6="",COUNTIFS(Checklist!$A:$A,$A6,Checklist!$C:$C,$C6,Checklist!$E:$E,"향상",Checklist!$H:$H,"<>"),COUNTIFS(Checklist!$A:$A,$A6,Checklist!$B:$B,$B6,Checklist!$C:$C,$C6,Checklist!$E:$E,"향상",Checklist!$H:$H,"<>")) -> 3 | G6: =IF($B6="",COUNTIFS(Checklist!$A:$A,$A6,Checklist!$C:$C,$C6,Checklist!$E:$E,"최적화",Checklist!$G:$G,"Y"),COUNTIFS(Checklist!$A:$A,$A6,Checklist!$B:$B,$B6,Checklist!$C:$C,$C6,Checklist!$E:$E,"최적화",Checklist!$G:$G,"Y")) -> 3 | H6: =IF($B6="",COUNTIFS(Checklist!$A:$A,$A6,Checklist!$C:$C,$C6,Checklist!$E:$E,"최적화",Checklist!$H:$H,"<>"),COUNTIFS(Checklist!$A:$A,$A6,Checklist!$B:$B,$B6,Checklist!$C:$C,$C6,Checklist!$E:$E,"최적화",Checklist!$H:$H,"<>")) -> 3 | I6: =IF(D6>0,0,IF(AND(F6=0,H6=0),0.4,IF(AND(F6>0,IF($B6="",COUNTIFS(Checklist!$A:$A,$A6,Checklist!$C:$C,$C6,Checklist!$E:$E,"향상",Checklist!$G:$G,"N"),COUNTIFS(Checklist!$A:$A,$A6,Checklist!$B:$B,$B6,Checklist!$C:$C,$C6,Checklist!$E:$E,"향상",Checklist!$G:$G,"N"))=0,H6>0,IF($B6="",COUNTIFS(Checklist!$A:$A,$A6,Checklist!$C:$C,$C6,Checklist!$E:$E,"최적화",Checklist!$G:$G,"N"),COUNTIFS(Checklist!$A:$A,$A6,Checklist!$B:$B,$B6,Checklist!$C:$C,$C6,Checklist!$E:$E,"최적화",Checklist!$G:$G,"N"))=0),0.7+0.3*IF(H6=0,0,G6/H6),0.4+0.3*IF(F6=0,0,E6/F6)))) -> 1
A7: 신원 | B7: 위험도 평가 | C7: 행동, 컨텍스트 기반 ID 및 생체 인식 | D7: =IF($B7="",COUNTIFS(Checklist!$A:$A,$A7,Checklist!$C:$C,$C7,Checklist!$E:$E,"초기",Checklist!$G:$G,"N"),COUNTIFS(Checklist!$A:$A,$A7,Checklist!$B:$B,$B7,Checklist!$C:$C,$C7,Checklist!$E:$E,"초기",Checklist!$G:$G,"N")) -> 0 | E7: =IF($B7="",COUNTIFS(Checklist!$A:$A,$A7,Checklist!$C:$C,$C7,Checklist!$E:$E,"향상",Checklist!$G:$G,"Y"),COUNTIFS(Checklist!$A:$A,$A7,Checklist!$B:$B,$B7,Checklist!$C:$C,$C7,Checklist!$E:$E,"향상",Checklist!$G:$G,"Y")) -> 2 | F7: =IF($B7="",COUNTIFS(Checklist!$A:$A,$A7,Checklist!$C:$C,$C7,Checklist!$E:$E,"향상",Checklist!$H:$H,"<>"),COUNTIFS(Checklist!$A:$A,$A7,Checklist!$B:$B,$B7,Checklist!$C:$C,$C7,Checklist!$E:$E,"향상",Checklist!$H:$H,"<>")) -> 2 | G7: =IF($B7="",COUNTIFS(Checklist!$A:$A,$A7,Checklist!$C:$C,$C7,Checklist!$E:$E,"최적화",Checklist!$G:$G,"Y"),COUNTIFS(Checklist!$A:$A,$A7,Checklist!$B:$B,$B7,Checklist!$C:$C,$C7,Checklist!$E:$E,"최적화",Checklist!$G:$G,"Y")) -> 2 | H7: =IF($B7="",COUNTIFS(Checklist!$A:$A,$A7,Checklist!$C:$C,$C7,Checklist!$E:$E,"최적화",Checklist!$H:$H,"<>"),COUNTIFS(Checklist!$A:$A,$A7,Checklist!$B:$B,$B7,Checklist!$C:$C,$C7,Checklist!$E:$E,"최적화",Checklist!$H:$H,"<>")) -> 2 | I7: =IF(D7>0,0,IF(AND(F7=0,H7=0),0.4,IF(AND(F7>0,IF($B7="",COUNTIFS(Checklist!$A:$A,$A7,Checklist!$C:$C,$C7,Checklist!$E:$E,"향상",Checklist!$G:$G,"N"),COUNTIFS(Checklist!$A:$A,$A7,Checklist!$B:$B,$B7,Checklist!$C:$C,$C7,Checklist!$E:$E,"향상",Checklist!$G:$G,"N"))=0,H7>0,IF($B7="",COUNTIFS(Checklist!$A:$A,$A7,Checklist!$C:$C,$C7,Checklist!$E:$E,"최적화",Checklist!$G:$G,"N"),COUNTIFS(Checklist!$A:$A,$A7,Checklist!$B:$B,$B7,Checklist!$C:$C,$C7,Checklist!$E:$E,"최적화",Checklist!$G:$G,"N"))=0),0.7+0.3*IF(H7=0,0,G7/H7),0.4+0.3*IF(F7=0,0,E7/F7)))) -> 1
A8: 신원 | B8: 접근 관리 | C8: 조건부 사용자 접근 | D8: =IF($B8="",COUNTIFS(Checklist!$A:$A,$A8,Checklist!$C:$C,$C8,Checklist!$E:$E,"초기",Checklist!$G:$G,"N"),COUNTIFS(Checklist!$A:$A,$A8,Checklist!$B:$B,$B8,Checklist!$C:$C,$C8,Checklist!$E:$E,"초기",Checklist!$G:$G,"N")) -> 0 | E8: =IF($B8="",COUNTIFS(Checklist!$A:$A,$A8,Checklist!$C:$C,$C8,Checklist!$E:$E,"향상",Checklist!$G:$G,"Y"),COUNTIFS(Checklist!$A:$A,$A8,Checklist!$B:$B,$B8,Checklist!$C:$C,$C8,Checklist!$E:$E,"향상",Checklist!$G:$G,"Y")) -> 3 | F8: =IF($B8="",COUNTIFS(Checklist!$A:$A,$A8,Checklist!$C:$C,$C8,Checklist!$E:$E,"향상",Checklist!$H:$H,"<>"),COUNTIFS(Checklist!$A:$A,$A8,Checklist!$B:$B,$B8,Checklist!$C:$C,$C8,Checklist!$E:$E,"향상",Checklist!$H:$H,"<>")) -> 3 | G8: =IF($B8="",COUNTIFS(Checklist!$A:$A,$A8,Checklist!$C:$C,$C8,Checklist!$E:$E,"최적화",Checklist!$G:$G,"Y"),COUNTIFS(Checklist!$A:$A,$A8,Checklist!$B:$B,$B8,Checklist!$C:$C,$C8,Checklist!$E:$E,"최적화",Checklist!$G:$G,"Y")) -> 2 | H8: =IF($B8="",COUNTIFS(Checklist!$A:$A,$A8,Checklist!$C:$C,$C8,Checklist!$E:$E,"최적화",Checklist!$H:$H,"<>"),COUNTIFS(Checklist!$A:$A,$A8,Checklist!$B:$B,$B8,Checklist!$C:$C,$C8,Checklist!$E:$E,"최적화",Checklist!$H:$H,"<>")) -> 2 | I8: =IF(D8>0,0,IF(AND(F8=0,H8=0),0.4,IF(AND(F8>0,IF($B8="",COUNTIFS(Checklist!$A:$A,$A8,Checklist!$C:$C,$C8,Checklist!$E:$E,"향상",Checklist!$G:$G,"N"),COUNTIFS(Checklist!$A:$A,$A8,Checklist!$B:$B,$B8,Checklist!$C:$C,$C8,Checklist!$E:$E,"향상",Checklist!$G:$G,"N"))=0,H8>0,IF($B8="",COUNTIFS(Checklist!$A:$A,$A8,Checklist!$C:$C,$C8,Checklist!$E:$E,"최적화",Checklist!$G:$G,"N"),COUNTIFS(Checklist!$A:$A,$A8,Checklist!$B:$B,$B8,Checklist!$C:$C,$C8,Checklist!$E:$E,"최적화",Checklist!$G:$G,"N"))=0),0.7+0.3*IF(H8=0,0,G8/H8),0.4+0.3*IF(F8=0,0,E8/F8)))) -> 1
A9: 신원 | B9: 접근 관리 | C9: 최소 권한 접근 | D9: =IF($B9="",COUNTIFS(Checklist!$A:$A,$A9,Checklist!$C:$C,$C9,Checklist!$E:$E,"초기",Checklist!$G:$G,"N"),COUNTIFS(Checklist!$A:$A,$A9,Checklist!$B:$B,$B9,Checklist!$C:$C,$C9,Checklist!$E:$E,"초기",Checklist!$G:$G,"N")) -> 0 | E9: =IF($B9="",COUNTIFS(Checklist!$A:$A,$A9,Checklist!$C:$C,$C9,Checklist!$E:$E,"향상",Checklist!$G:$G,"Y"),COUNTIFS(Checklist!$A:$A,$A9,Checklist!$B:$B,$B9,Checklist!$C:$C,$C9,Checklist!$E:$E,"향상",Checklist!$G:$G,"Y")) -> 2 | F9: =IF($B9="",COUNTIFS(Checklist!$A:$A,$A9,Checklist!$C:$C,$C9,Checklist!$E:$E,"향상",Checklist!$H:$H,"<>"),COUNTIFS(Checklist!$A:$A,$A9,Checklist!$B:$B,$B9,Checklist!$C:$C,$C9,Checklist!$E:$E,"향상",Checklist!$H:$H,"<>")) -> 2 | G9: =IF($B9="",COUNTIFS(Checklist!$A:$A,$A9,Checklist!$C:$C,$C9,Checklist!$E:$E,"최적화",Checklist!$G:$G,"Y"),COUNTIFS(Checklist!$A:$A,$A9,Checklist!$B:$B,$B9,Checklist!$C:$C,$C9,Checklist!$E:$E,"최적화",Checklist!$G:$G,"Y")) -> 2 | H9: =IF($B9="",COUNTIFS(Checklist!$A:$A,$A9,Checklist!$C:$C,$C9,Checklist!$E:$E,"최적화",Checklist!$H:$H,"<>"),COUNTIFS(Checklist!$A:$A,$A9,Checklist!$B:$B,$B9,Checklist!$C:$C,$C9,Checklist!$E:$E,"최적화",Checklist!$H:$H,"<>")) -> 2 | I9: =IF(D9>0,0,IF(AND(F9=0,H9=0),0.4,IF(AND(F9>0,IF($B9="",COUNTIFS(Checklist!$A:$A,$A9,Checklist!$C:$C,$C9,Checklist!$E:$E,"향상",Checklist!$G:$G,"N"),COUNTIFS(Checklist!$A:$A,$A9,Checklist!$B:$B,$B9,Checklist!$C:$C,$C9,Checklist!$E:$E,"향상",Checklist!$G:$G,"N"))=0,H9>0,IF($B9="",COUNTIFS(Checklist!$A:$A,$A9,Checklist!$C:$C,$C9,Checklist!$E:$E,"최적화",Checklist!$G:$G,"N"),COUNTIFS(Checklist!$A:$A,$A9,Checklist!$B:$B,$B9,Checklist!$C:$C,$C9,Checklist!$E:$E,"최적화",Checklist!$G:$G,"N"))=0),0.7+0.3*IF(H9=0,0,G9/H9),0.4+0.3*IF(F9=0,0,E9/F9)))) -> 1
A10: 기기 및 엔드포인트 | B10: 정책 준수 모니터링 | C10: 기기 감지 및 규정 준수 | D10: =IF($B10="",COUNTIFS(Checklist!$A:$A,$A10,Checklist!$C:$C,$C10,Checklist!$E:$E,"초기",Checklist!$G:$G,"N"),COUNTIFS(Checklist!$A:$A,$A10,Checklist!$B:$B,$B10,Checklist!$C:$C,$C10,Checklist!$E:$E,"초기",Checklist!$G:$G,"N")) -> 0 | E10: =IF($B10="",COUNTIFS(Checklist!$A:$A,$A10,Checklist!$C:$C,$C10,Checklist!$E:$E,"향상",Checklist!$G:$G,"Y"),COUNTIFS(Checklist!$A:$A,$A10,Checklist!$B:$B,$B10,Checklist!$C:$C,$C10,Checklist!$E:$E,"향상",Checklist!$G:$G,"Y")) -> 3 | F10: =IF($B10="",COUNTIFS(Checklist!$A:$A,$A10,Checklist!$C:$C,$C10,Checklist!$E:$E,"향상",Checklist!$H:$H,"<>"),COUNTIFS(Checklist!$A:$A,$A10,Checklist!$B:$B,$B10,Checklist!$C:$C,$C10,Checklist!$E:$E,"향상",Checklist!$H:$H,"<>")) -> 3 | G10: =IF($B10="",COUNTIFS(Checklist!$A:$A,$A10,Checklist!$C:$C,$C10,Checklist!$E:$E,"최적화",Checklist!$G:$G,"Y"),COUNTIFS(Checklist!$A:$A,$A10,Checklist!$B:$B,$B10,Checklist!$C:$C,$C10,Checklist!$E:$E,"최적화",Checklist!$G:$G,"Y")) -> 3 | H10: =IF($B10="",COUNTIFS(Checklist!$A:$A,$A10,Checklist!$C:$C,$C10,Checklist!$E:$E,"최적화",Checklist!$H:$H,"<>"),COUNTIFS(Checklist!$A:$A,$A10,Checklist!$B:$B,$B10,Checklist!$C:$C,$C10,Checklist!$E:$E,"최적화",Checklist!$H:$H,"<>")) -> 3 | I10: =IF(D10>0,0,IF(AND(F10=0,H10=0),0.4,IF(AND(F10>0,IF($B10="",COUNTIFS(Checklist!$A:$A,$A10,Checklist!$C:$C,$C10,Checklist!$E:$E,"향상",Checklist!$G:$G,"N"),COUNTIFS(Checklist!$A:$A,$A10,Checklist!$B:$B,$B10,Checklist!$C:$C,$C10,Checklist!$E:$E,"향상",Checklist!$G:$G,"N"))=0,H10>0,IF($B10="",COUNTIFS(Checklist!$A:$A,$A10,Checklist!$C:$C,$C10,Checklist!$E:$E,"최적화",Checklist!$G:$G,"N"),COUNTIFS(Checklist!$A:$A,$A10,Checklist!$B:$B,$B10,Checklist!$C:$C,$C10,Checklist!$E:$E,"최적화",Checklist!$G:$G,"N"))=0),0.7+0.3*IF(H10=0,0,G10/H10),0.4+0.3*IF(F10=0,0,E10/F10)))) -> 1
A11: 기기 및 엔드포인트 | B11: 데이터 접근제어 | C11: 실시간 검사를 통한 기기 권한 부여 | D11: =IF($B11="",COUNTIFS(Checklist!$A:$A,$A11,Checklist!$C:$C,$C11,Checklist!$E:$E,"초기",Checklist!$G:$G,"N"),COUNTIFS(Checklist!$A:$A,$A11,Checklist!$B:$B,$B11,Checklist!$C:$C,$C11,Checklist!$E:$E,"초기",Checklist!$G:$G,"N")) -> 0 | E11: =IF($B11="",COUNTIFS(Checklist!$A:$A,$A11,Checklist!$C:$C,$C11,Checklist!$E:$E,"향상",Checklist!$G:$G,"Y"),COUNTIFS(Checklist!$A:$A,$A11,Checklist!$B:$B,$B11,Checklist!$C:$C,$C11,Checklist!$E:$E,"향상",Checklist!$G:$G,"Y")) -> 3 | F11: =IF($B11="",COUNTIFS(Checklist!$A:$A,$A11,Checklist!$C:$C,$C11,Checklist!$E:$E,"향상",Checklist!$H:$H,"<>"),COUNTIFS(Checklist!$A:$A,$A11,Checklist!$B:$B,$B11,Checklist!$C:$C,$C11,Checklist!$E:$E,"향상",Checklist!$H:$H,"<>")) -> 3 | G11: =IF($B11="",COUNTIFS(Checklist!$A:$A,$A11,Checklist!$C:$C,$C11,Checklist!$E:$E,"최적화",Checklist!$G:$G,"Y"),COUNTIFS(Checklist!$A:$A,$A11,Checklist!$B:$B,$B11,Checklist!$C:$C,$C11,Checklist!$E:$E,"최적화",Checklist!$G:$G,"Y")) -> 4 | H11: =IF($B11="",COUNTIFS(Checklist!$A:$A,$A11,Checklist!$C:$C,$C11,Checklist!$E:$E,"최적화",Checklist!$H:$H,"<>"),COUNTIFS(Checklist!$A:$A,$A11,Checklist!$B:$B,$B11,Checklist!$C:$C,$C11,Checklist!$E:$E,"최적화",Checklist!$H:$H,"<>")) -> 4 | I11: =IF(D11>0,0,IF(AND(F11=0,H11=0),0.4,IF(AND(F11>0,IF($B11="",COUNTIFS(Checklist!$A:$A,$A11,Checklist!$C:$C,$C11,Checklist!$E:$E,"향상",Checklist!$G:$G,"N"),COUNTIFS(Checklist!$A:$A,$A11,Checklist!$B:$B,$B11,Checklist!$C:$C,$C11,Checklist!$E:$E,"향상",Checklist!$G:$G,"N"))=0,H11>0,IF($B11="",COUNTIFS(Checklist!$A:$A,$A11,Checklist!$C:$C,$C11,Checklist!$E:$E,"최적화",Checklist!$G:$G,"N"),COUNTIFS(Checklist!$A:$A,$A11,Checklist!$B:$B,$B11,Checklist!$C:$C,$C11,Checklist!$E:$E,"최적화",Checklist!$G:$G,"N"))=0),0.7+0.3*IF(H11=0,0,G11/H11),0.4+0.3*IF(F11=0,0,E11/F11)))) -> 1
A12: 기기 및 엔드포인트 | B12: 자산 관리 | C12: 기기 인벤토리 | D12: =IF($B12="",COUNTIFS(Checklist!$A:$A,$A12,Checklist!$C:$C,$C12,Checklist!$E:$E,"초기",Checklist!$G:$G,"N"),COUNTIFS(Checklist!$A:$A,$A12,Checklist!$B:$B,$B12,Checklist!$C:$C,$C12,Checklist!$E:$E,"초기",Checklist!$G:$G,"N")) -> 0 | E12: =IF($B12="",COUNTIFS(Checklist!$A:$A,$A12,Checklist!$C:$C,$C12,Checklist!$E:$E,"향상",Checklist!$G:$G,"Y"),COUNTIFS(Checklist!$A:$A,$A12,Checklist!$B:$B,$B12,Checklist!$C:$C,$C12,Checklist!$E:$E,"향상",Checklist!$G:$G,"Y")) -> 3 | F12: =IF($B12="",COUNTIFS(Checklist!$A:$A,$A12,Checklist!$C:$C,$C12,Checklist!$E:$E,"향상",Checklist!$H:$H,"<>"),COUNTIFS(Checklist!$A:$A,$A12,Checklist!$B:$B,$B12,Checklist!$C:$C,$C12,Checklist!$E:$E,"향상",Checklist!$H:$H,"<>")) -> 3 | G12: =IF($B12="",COUNTIFS(Checklist!$A:$A,$A12,Checklist!$C:$C,$C12,Checklist!$E:$E,"최적화",Checklist!$G:$G,"Y"),COUNTIFS(Checklist!$A:$A,$A12,Checklist!$B:$B,$B12,Checklist!$C:$C,$C12,Checklist!$E:$E,"최적화",Checklist!$G:$G,"Y")) -> 2 | H12: =IF($B12="",COUNTIFS(Checklist!$A:$A,$A12,Checklist!$C:$C,$C12,Checklist!$E:$E,"최적화",Checklist!$H:$H,"<>"),COUNTIFS(Checklist!$A:$A,$A12,Checklist!$B:$B,$B12,Checklist!$C:$C,$C12,Checklist!$E:$E,"최적화",Checklist!$H:$H,"<>")) -> 2 | I12: =IF(D12>0,0,IF(AND(F12=0,H12=0),0.4,IF(AND(F12>0,IF($B12="",COUNTIFS(Checklist!$A:$A,$A12,Checklist!$C:$C,$C12,Checklist!$E:$E,"향상",Checklist!$G:$G,"N"),COUNTIFS(Checklist!$A:$A,$A12,Checklist!$B:$B,$B12,Checklist!$C:$C,$C12,Checklist!$E:$E,"향상",Checklist!$G:$G,"N"))=0,H12>0,IF($B12="",COUNTIFS(Checklist!$A:$A,$A12,Checklist!$C:$C,$C12,Checklist!$E:$E,"최적화",Checklist!$G:$G,"N"),COUNTIFS(Checklist!$A:$A,$A12,Checklist!$B:$B,$B12,Checklist!$C:$C,$C12,Checklist!$E:$E,"최적화",Checklist!$G:$G,"N"))=0),0.7+0.3*IF(H12=0,0,G12/H12),0.4+0.3*IF(F12=0,0,E12/F12)))) -> 1
A13: 기기 및 엔드포인트 | B13: 자산 관리 | C13: 통합 엔드포인트 관리 및 모바일 기기 관리 | D13: =IF($B13="",COUNTIFS(Checklist!$A:$A,$A13,Checklist!$C:$C,$C13,Checklist!$E:$E,"초기",Checklist!$G:$G,"N"),COUNTIFS(Checklist!$A:$A,$A13,Checklist!$B:$B,$B13,Checklist!$C:$C,$C13,Checklist!$E:$E,"초기",Checklist!$G:$G,"N")) -> 0 | E13: =IF($B13="",COUNTIFS(Checklist!$A:$A,$A13,Checklist!$C:$C,$C13,Checklist!$E:$E,"향상",Checklist!$G:$G,"Y"),COUNTIFS(Checklist!$A:$A,$A13,Checklist!$B:$B,$B13,Checklist!$C:$C,$C13,Checklist!$E:$E,"향상",Checklist!$G:$G,"Y")) -> 2 | F13: =IF($B13="",COUNTIFS(Checklist!$A:$A,$A13,Checklist!$C:$C,$C13,Checklist!$E:$E,"향상",Checklist!$H:$H,"<>"),COUNTIFS(Checklist!$A:$A,$A13,Checklist!$B:$B,$B13,Checklist!$C:$C,$C13,Checklist!$E:$E,"향상",Checklist!$H:$H,"<>")) -> 2 | G13: =IF($B13="",COUNTIFS(Checklist!$A:$A,$A13,Checklist!$C:$C,$C13,Checklist!$E:$E,"최적화",Checklist!$G:$G,"Y"),COUNTIFS(Checklist!$A:$A,$A13,Checklist!$B:$B,$B13,Checklist!$C:$C,$C13,Checklist!$E:$E,"최적화",Checklist!$G:$G,"Y")) -> 2 | H13: =IF($B13="",COUNTIFS(Checklist!$A:$A,$A13,Checklist!$C:$C,$C13,Checklist!$E:$E,"최적화",Checklist!$H:$H,"<>"),COUNTIFS(Checklist!$A:$A,$A13,Checklist!$B:$B,$B13,Checklist!$C:$C,$C13,Checklist!$E:$E,"최적화",Checklist!$H:$H,"<>")) -> 2 | I13: =IF(D13>0,0,IF(AND(F13=0,H13=0),0.4,IF(AND(F13>0,IF($B13="",COUNTIFS(Checklist!$A:$A,$A13,Checklist!$C:$C,$C13,Checklist!$E:$E,"향상",Checklist!$G:$G,"N"),COUNTIFS(Checklist!$A:$A,$A13,Checklist!$B:$B,$B13,Checklist!$C:$C,$C13,Checklist!$E:$E,"향상",Checklist!$G:$G,"N"))=0,H13>0,IF($B13="",COUNTIFS(Checklist!$A:$A,$A13,Checklist!$C:$C,$C13,Checklist!$E:$E,"최적화",Checklist!$G:$G,"N"),COUNTIFS(Checklist!$A:$A,$A13,Checklist!$B:$B,$B13,Checklist!$C:$C,$C13,Checklist!$E:$E,"최적화",Checklist!$G:$G,"N"))=0),0.7+0.3*IF(H13=0,0,G13/H13),0.4+0.3*IF(F13=0,0,E13/F13)))) -> 1
... A36: 데이터 | B36: 데이터 손실 방지 | C36: 데이터 모니터링 및 감지 | D36: =IF($B36="",COUNTIFS(Checklist!$A:$A,$A36,Checklist!$C:$C,$C36,Checklist!$E:$E,"초기",Checklist!$G:$G,"N"),COUNTIFS(Checklist!$A:$A,$A36,Checklist!$B:$B,$B36,Checklist!$C:$C,$C36,Checklist!$E:$E,"초기",Checklist!$G:$G,"N")) -> 0 | E36: =IF($B36="",COUNTIFS(Checklist!$A:$A,$A36,Checklist!$C:$C,$C36,Checklist!$E:$E,"향상",Checklist!$G:$G,"Y"),COUNTIFS(Checklist!$A:$A,$A36,Checklist!$B:$B,$B36,Checklist!$C:$C,$C36,Checklist!$E:$E,"향상",Checklist!$G:$G,"Y")) -> 3 | F36: =IF($B36="",COUNTIFS(Checklist!$A:$A,$A36,Checklist!$C:$C,$C36,Checklist!$E:$E,"향상",Checklist!$H:$H,"<>"),COUNTIFS(Checklist!$A:$A,$A36,Checklist!$B:$B,$B36,Checklist!$C:$C,$C36,Checklist!$E:$E,"향상",Checklist!$H:$H,"<>")) -> 3 | G36: =IF($B36="",COUNTIFS(Checklist!$A:$A,$A36,Checklist!$C:$C,$C36,Checklist!$E:$E,"최적화",Checklist!$G:$G,"Y"),COUNTIFS(Checklist!$A:$A,$A36,Checklist!$B:$B,$B36,Checklist!$C:$C,$C36,Checklist!$E:$E,"최적화",Checklist!$G:$G,"Y")) -> 3 | H36: =IF($B36="",COUNTIFS(Checklist!$A:$A,$A36,Checklist!$C:$C,$C36,Checklist!$E:$E,"최적화",Checklist!$H:$H,"<>"),COUNTIFS(Checklist!$A:$A,$A36,Checklist!$B:$B,$B36,Checklist!$C:$C,$C36,Checklist!$E:$E,"최적화",Checklist!$H:$H,"<>")) -> 3 | I36: =IF(D36>0,0,IF(AND(F36=0,H36=0),0.4,IF(AND(F36>0,IF($B36="",COUNTIFS(Checklist!$A:$A,$A36,Checklist!$C:$C,$C36,Checklist!$E:$E,"향상",Checklist!$G:$G,"N"),COUNTIFS(Checklist!$A:$A,$A36,Checklist!$B:$B,$B36,Checklist!$C:$C,$C36,Checklist!$E:$E,"향상",Checklist!$G:$G,"N"))=0,H36>0,IF($B36="",COUNTIFS(Checklist!$A:$A,$A36,Checklist!$C:$C,$C36,Checklist!$E:$E,"최적화",Checklist!$G:$G,"N"),COUNTIFS(Checklist!$A:$A,$A36,Checklist!$B:$B,$B36,Checklist!$C:$C,$C36,Checklist!$E:$E,"최적화",Checklist!$G:$G,"N"))=0),0.7+0.3*IF(H36=0,0,G36/H36),0.4+0.3*IF(F36=0,0,E36/F36)))) -> 1
A37: 가시성 및 분석 | C37: 모든 관련 활동 기록 | D37: =IF($B37="",COUNTIFS(Checklist!$A:$A,$A37,Checklist!$C:$C,$C37,Checklist!$E:$E,"초기",Checklist!$G:$G,"N"),COUNTIFS(Checklist!$A:$A,$A37,Checklist!$B:$B,$B37,Checklist!$C:$C,$C37,Checklist!$E:$E,"초기",Checklist!$G:$G,"N")) -> 0 | E37: =IF($B37="",COUNTIFS(Checklist!$A:$A,$A37,Checklist!$C:$C,$C37,Checklist!$E:$E,"향상",Checklist!$G:$G,"Y"),COUNTIFS(Checklist!$A:$A,$A37,Checklist!$B:$B,$B37,Checklist!$C:$C,$C37,Checklist!$E:$E,"향상",Checklist!$G:$G,"Y")) -> 4 | F37: =IF($B37="",COUNTIFS(Checklist!$A:$A,$A37,Checklist!$C:$C,$C37,Checklist!$E:$E,"향상",Checklist!$H:$H,"<>"),COUNTIFS(Checklist!$A:$A,$A37,Checklist!$B:$B,$B37,Checklist!$C:$C,$C37,Checklist!$E:$E,"향상",Checklist!$H:$H,"<>")) -> 4 | G37: =IF($B37="",COUNTIFS(Checklist!$A:$A,$A37,Checklist!$C:$C,$C37,Checklist!$E:$E,"최적화",Checklist!$G:$G,"Y"),COUNTIFS(Checklist!$A:$A,$A37,Checklist!$B:$B,$B37,Checklist!$C:$C,$C37,Checklist!$E:$E,"최적화",Checklist!$G:$G,"Y")) -> 5 | H37: =IF($B37="",COUNTIFS(Checklist!$A:$A,$A37,Checklist!$C:$C,$C37,Checklist!$E:$E,"최적화",Checklist!$H:$H,"<>"),COUNTIFS(Checklist!$A:$A,$A37,Checklist!$B:$B,$B37,Checklist!$C:$C,$C37,Checklist!$E:$E,"최적화",Checklist!$H:$H,"<>")) -> 5 | I37: =IF(D37>0,0,IF(AND(F37=0,H37=0),0.4,IF(AND(F37>0,IF($B37="",COUNTIFS(Checklist!$A:$A,$A37,Checklist!$C:$C,$C37,Checklist!$E:$E,"향상",Checklist!$G:$G,"N"),COUNTIFS(Checklist!$A:$A,$A37,Checklist!$B:$B,$B37,Checklist!$C:$C,$C37,Checklist!$E:$E,"향상",Checklist!$G:$G,"N"))=0,H37>0,IF($B37="",COUNTIFS(Checklist!$A:$A,$A37,Checklist!$C:$C,$C37,Checklist!$E:$E,"최적화",Checklist!$G:$G,"N"),COUNTIFS(Checklist!$A:$A,$A37,Checklist!$B:$B,$B37,Checklist!$C:$C,$C37,Checklist!$E:$E,"최적화",Checklist!$G:$G,"N"))=0),0.7+0.3*IF(H37=0,0,G37/H37),0.4+0.3*IF(F37=0,0,E37/F37)))) -> 1
A38: 가시성 및 분석 | C38: 중앙집중적 보안 정보 및 이벤트 관리 | D38: =IF($B38="",COUNTIFS(Checklist!$A:$A,$A38,Checklist!$C:$C,$C38,Checklist!$E:$E,"초기",Checklist!$G:$G,"N"),COUNTIFS(Checklist!$A:$A,$A38,Checklist!$B:$B,$B38,Checklist!$C:$C,$C38,Checklist!$E:$E,"초기",Checklist!$G:$G,"N")) -> 0 | E38: =IF($B38="",COUNTIFS(Checklist!$A:$A,$A38,Checklist!$C:$C,$C38,Checklist!$E:$E,"향상",Checklist!$G:$G,"Y"),COUNTIFS(Checklist!$A:$A,$A38,Checklist!$B:$B,$B38,Checklist!$C:$C,$C38,Checklist!$E:$E,"향상",Checklist!$G:$G,"Y")) -> 2 | F38: =IF($B38="",COUNTIFS(Checklist!$A:$A,$A38,Checklist!$C:$C,$C38,Checklist!$E:$E,"향상",Checklist!$H:$H,"<>"),COUNTIFS(Checklist!$A:$A,$A38,Checklist!$B:$B,$B38,Checklist!$C:$C,$C38,Checklist!$E:$E,"향상",Checklist!$H:$H,"<>")) -> 2 | G38: =IF($B38="",COUNTIFS(Checklist!$A:$A,$A38,Checklist!$C:$C,$C38,Checklist!$E:$E,"최적화",Checklist!$G:$G,"Y"),COUNTIFS(Checklist!$A:$A,$A38,Checklist!$B:$B,$B38,Checklist!$C:$C,$C38,Checklist!$E:$E,"최적화",Checklist!$G:$G,"Y")) -> 3 | H38: =IF($B38="",COUNTIFS(Checklist!$A:$A,$A38,Checklist!$C:$C,$C38,Checklist!$E:$E,"최적화",Checklist!$H:$H,"<>"),COUNTIFS(Checklist!$A:$A,$A38,Checklist!$B:$B,$B38,Checklist!$C:$C,$C38,Checklist!$E:$E,"최적화",Checklist!$H:$H,"<>")) -> 3 | I38: =IF(D38>0,0,IF(AND(F38=0,H38=0),0.4,IF(AND(F38>0,IF($B38="",COUNTIFS(Checklist!$A:$A,$A38,Checklist!$C:$C,$C38,Checklist!$E:$E,"향상",Checklist!$G:$G,"N"),COUNTIFS(Checklist!$A:$A,$A38,Checklist!$B:$B,$B38,Checklist!$C:$C,$C38,Checklist!$E:$E,"향상",Checklist!$G:$G,"N"))=0,H38>0,IF($B38="",COUNTIFS(Checklist!$A:$A,$A38,Checklist!$C:$C,$C38,Checklist!$E:$E,"최적화",Checklist!$G:$G,"N"),COUNTIFS(Checklist!$A:$A,$A38,Checklist!$B:$B,$B38,Checklist!$C:$C,$C38,Checklist!$E:$E,"최적화",Checklist!$G:$G,"N"))=0),0.7+0.3*IF(H38=0,0,G38/H38),0.4+0.3*IF(F38=0,0,E38/F38)))) -> 1
A39: 가시성 및 분석 | C39: 보안 위협 분석 | D39: =IF($B39="",COUNTIFS(Checklist!$A:$A,$A39,Checklist!$C:$C,$C39,Checklist!$E:$E,"초기",Checklist!$G:$G,"N"),COUNTIFS(Checklist!$A:$A,$A39,Checklist!$B:$B,$B39,Checklist!$C:$C,$C39,Checklist!$E:$E,"초기",Checklist!$G:$G,"N")) -> 0 | E39: =IF($B39="",COUNTIFS(Checklist!$A:$A,$A39,Checklist!$C:$C,$C39,Checklist!$E:$E,"향상",Checklist!$G:$G,"Y"),COUNTIFS(Checklist!$A:$A,$A39,Checklist!$B:$B,$B39,Checklist!$C:$C,$C39,Checklist!$E:$E,"향상",Checklist!$G:$G,"Y")) -> 3 | F39: =IF($B39="",COUNTIFS(Checklist!$A:$A,$A39,Checklist!$C:$C,$C39,Checklist!$E:$E,"향상",Checklist!$H:$H,"<>"),COUNTIFS(Checklist!$A:$A,$A39,Checklist!$B:$B,$B39,Checklist!$C:$C,$C39,Checklist!$E:$E,"향상",Checklist!$H:$H,"<>")) -> 3 | G39: =IF($B39="",COUNTIFS(Checklist!$A:$A,$A39,Checklist!$C:$C,$C39,Checklist!$E:$E,"최적화",Checklist!$G:$G,"Y"),COUNTIFS(Checklist!$A:$A,$A39,Checklist!$B:$B,$B39,Checklist!$C:$C,$C39,Checklist!$E:$E,"최적화",Checklist!$G:$G,"Y")) -> 3 | H39: =IF($B39="",COUNTIFS(Checklist!$A:$A,$A39,Checklist!$C:$C,$C39,Checklist!$E:$E,"최적화",Checklist!$H:$H,"<>"),COUNTIFS(Checklist!$A:$A,$A39,Checklist!$B:$B,$B39,Checklist!$C:$C,$C39,Checklist!$E:$E,"최적화",Checklist!$H:$H,"<>")) -> 3 | I39: =IF(D39>0,0,IF(AND(F39=0,H39=0),0.4,IF(AND(F39>0,IF($B39="",COUNTIFS(Checklist!$A:$A,$A39,Checklist!$C:$C,$C39,Checklist!$E:$E,"향상",Checklist!$G:$G,"N"),COUNTIFS(Checklist!$A:$A,$A39,Checklist!$B:$B,$B39,Checklist!$C:$C,$C39,Checklist!$E:$E,"향상",Checklist!$G:$G,"N"))=0,H39>0,IF($B39="",COUNTIFS(Checklist!$A:$A,$A39,Checklist!$C:$C,$C39,Checklist!$E:$E,"최적화",Checklist!$G:$G,"N"),COUNTIFS(Checklist!$A:$A,$A39,Checklist!$B:$B,$B39,Checklist!$C:$C,$C39,Checklist!$E:$E,"최적화",Checklist!$G:$G,"N"))=0),0.7+0.3*IF(H39=0,0,G39/H39),0.4+0.3*IF(F39=0,0,E39/F39)))) -> 1
A40: 가시성 및 분석 | C40: 사용자 및 기기 동작 분석 | D40: =IF($B40="",COUNTIFS(Checklist!$A:$A,$A40,Checklist!$C:$C,$C40,Checklist!$E:$E,"초기",Checklist!$G:$G,"N"),COUNTIFS(Checklist!$A:$A,$A40,Checklist!$B:$B,$B40,Checklist!$C:$C,$C40,Checklist!$E:$E,"초기",Checklist!$G:$G,"N")) -> 0 | E40: =IF($B40="",COUNTIFS(Checklist!$A:$A,$A40,Checklist!$C:$C,$C40,Checklist!$E:$E,"향상",Checklist!$G:$G,"Y"),COUNTIFS(Checklist!$A:$A,$A40,Checklist!$B:$B,$B40,Checklist!$C:$C,$C40,Checklist!$E:$E,"향상",Checklist!$G:$G,"Y")) -> 4 | F40: =IF($B40="",COUNTIFS(Checklist!$A:$A,$A40,Checklist!$C:$C,$C40,Checklist!$E:$E,"향상",Checklist!$H:$H,"<>"),COUNTIFS(Checklist!$A:$A,$A40,Checklist!$B:$B,$B40,Checklist!$C:$C,$C40,Checklist!$E:$E,"향상",Checklist!$H:$H,"<>")) -> 4 | G40: =IF($B40="",COUNTIFS(Checklist!$A:$A,$A40,Checklist!$C:$C,$C40,Checklist!$E:$E,"최적화",Checklist!$G:$G,"Y"),COUNTIFS(Checklist!$A:$A,$A40,Checklist!$B:$B,$B40,Checklist!$C:$C,$C40,Checklist!$E:$E,"최적화",Checklist!$G:$G,"Y")) -> 3 | H40: =IF($B40="",COUNTIFS(Checklist!$A:$A,$A40,Checklist!$C:$C,$C40,Checklist!$E:$E,"최적화",Checklist!$H:$H,"<>"),COUNTIFS(Checklist!$A:$A,$A40,Checklist!$B:$B,$B40,Checklist!$C:$C,$C40,Checklist!$E:$E,"최적화",Checklist!$H:$H,"<>")) -> 3 | I40: =IF(D40>0,0,IF(AND(F40=0,H40=0),0.4,IF(AND(F40>0,IF($B40="",COUNTIFS(Checklist!$A:$A,$A40,Checklist!$C:$C,$C40,Checklist!$E:$E,"향상",Checklist!$G:$G,"N"),COUNTIFS(Checklist!$A:$A,$A40,Checklist!$B:$B,$B40,Checklist!$C:$C,$C40,Checklist!$E:$E,"향상",Checklist!$G:$G,"N"))=0,H40>0,IF($B40="",COUNTIFS(Checklist!$A:$A,$A40,Checklist!$C:$C,$C40,Checklist!$E:$E,"최적화",Checklist!$G:$G,"N"),COUNTIFS(Checklist!$A:$A,$A40,Checklist!$B:$B,$B40,Checklist!$C:$C,$C40,Checklist!$E:$E,"최적화",Checklist!$G:$G,"N"))=0),0.7+0.3*IF(H40=0,0,G40/H40),0.4+0.3*IF(F40=0,0,E40/F40)))) -> 1
A41: 가시성 및 분석 | C41: 위협 인텔리전스 통합 | D41: =IF($B41="",COUNTIFS(Checklist!$A:$A,$A41,Checklist!$C:$C,$C41,Checklist!$E:$E,"초기",Checklist!$G:$G,"N"),COUNTIFS(Checklist!$A:$A,$A41,Checklist!$B:$B,$B41,Checklist!$C:$C,$C41,Checklist!$E:$E,"초기",Checklist!$G:$G,"N")) -> 0 | E41: =IF($B41="",COUNTIFS(Checklist!$A:$A,$A41,Checklist!$C:$C,$C41,Checklist!$E:$E,"향상",Checklist!$G:$G,"Y"),COUNTIFS(Checklist!$A:$A,$A41,Checklist!$B:$B,$B41,Checklist!$C:$C,$C41,Checklist!$E:$E,"향상",Checklist!$G:$G,"Y")) -> 2 | F41: =IF($B41="",COUNTIFS(Checklist!$A:$A,$A41,Checklist!$C:$C,$C41,Checklist!$E:$E,"향상",Checklist!$H:$H,"<>"),COUNTIFS(Checklist!$A:$A,$A41,Checklist!$B:$B,$B41,Checklist!$C:$C,$C41,Checklist!$E:$E,"향상",Checklist!$H:$H,"<>")) -> 2 | G41: =IF($B41="",COUNTIFS(Checklist!$A:$A,$A41,Checklist!$C:$C,$C41,Checklist!$E:$E,"최적화",Checklist!$G:$G,"Y"),COUNTIFS(Checklist!$A:$A,$A41,Checklist!$B:$B,$B41,Checklist!$C:$C,$C41,Checklist!$E:$E,"최적화",Checklist!$G:$G,"Y")) -> 3 | H41: =IF($B41="",COUNTIFS(Checklist!$A:$A,$A41,Checklist!$C:$C,$C41,Checklist!$E:$E,"최적화",Checklist!$H:$H,"<>"),COUNTIFS(Checklist!$A:$A,$A41,Checklist!$B:$B,$B41,Checklist!$C:$C,$C41,Checklist!$E:$E,"최적화",Checklist!$H:$H,"<>")) -> 3 | I41: =IF(D41>0,0,IF(AND(F41=0,H41=0),0.4,IF(AND(F41>0,IF($B41="",COUNTIFS(Checklist!$A:$A,$A41,Checklist!$C:$C,$C41,Checklist!$E:$E,"향상",Checklist!$G:$G,"N"),COUNTIFS(Checklist!$A:$A,$A41,Checklist!$B:$B,$B41,Checklist!$C:$C,$C41,Checklist!$E:$E,"향상",Checklist!$G:$G,"N"))=0,H41>0,IF($B41="",COUNTIFS(Checklist!$A:$A,$A41,Checklist!$C:$C,$C41,Checklist!$E:$E,"최적화",Checklist!$G:$G,"N"),COUNTIFS(Checklist!$A:$A,$A41,Checklist!$B:$B,$B41,Checklist!$C:$C,$C41,Checklist!$E:$E,"최적화",Checklist!$G:$G,"N"))=0),0.7+0.3*IF(H41=0,0,G41/H41),0.4+0.3*IF(F41=0,0,E41/F41)))) -> 1
A42: 가시성 및 분석 | C42: 자동화된 동적 정책 | D42: =IF($B42="",COUNTIFS(Checklist!$A:$A,$A42,Checklist!$C:$C,$C42,Checklist!$E:$E,"초기",Checklist!$G:$G,"N"),COUNTIFS(Checklist!$A:$A,$A42,Checklist!$B:$B,$B42,Checklist!$C:$C,$C42,Checklist!$E:$E,"초기",Checklist!$G:$G,"N")) -> 0 | E42: =IF($B42="",COUNTIFS(Checklist!$A:$A,$A42,Checklist!$C:$C,$C42,Checklist!$E:$E,"향상",Checklist!$G:$G,"Y"),COUNTIFS(Checklist!$A:$A,$A42,Checklist!$B:$B,$B42,Checklist!$C:$C,$C42,Checklist!$E:$E,"향상",Checklist!$G:$G,"Y")) -> 1 | F42: =IF($B42="",COUNTIFS(Checklist!$A:$A,$A42,Checklist!$C:$C,$C42,Checklist!$E:$E,"향상",Checklist!$H:$H,"<>"),COUNTIFS(Checklist!$A:$A,$A42,Checklist!$B:$B,$B42,Checklist!$C:$C,$C42,Checklist!$E:$E,"향상",Checklist!$H:$H,"<>")) -> 1 | G42: =IF($B42="",COUNTIFS(Checklist!$A:$A,$A42,Checklist!$C:$C,$C42,Checklist!$E:$E,"최적화",Checklist!$G:$G,"Y"),COUNTIFS(Checklist!$A:$A,$A42,Checklist!$B:$B,$B42,Checklist!$C:$C,$C42,Checklist!$E:$E,"최적화",Checklist!$G:$G,"Y")) -> 3 | H42: =IF($B42="",COUNTIFS(Checklist!$A:$A,$A42,Checklist!$C:$C,$C42,Checklist!$E:$E,"최적화",Checklist!$H:$H,"<>"),COUNTIFS(Checklist!$A:$A,$A42,Checklist!$B:$B,$B42,Checklist!$C:$C,$C42,Checklist!$E:$E,"최적화",Checklist!$H:$H,"<>")) -> 3 | I42: =IF(D42>0,0,IF(AND(F42=0,H42=0),0.4,IF(AND(F42>0,IF($B42="",COUNTIFS(Checklist!$A:$A,$A42,Checklist!$C:$C,$C42,Checklist!$E:$E,"향상",Checklist!$G:$G,"N"),COUNTIFS(Checklist!$A:$A,$A42,Checklist!$B:$B,$B42,Checklist!$C:$C,$C42,Checklist!$E:$E,"향상",Checklist!$G:$G,"N"))=0,H42>0,IF($B42="",COUNTIFS(Checklist!$A:$A,$A42,Checklist!$C:$C,$C42,Checklist!$E:$E,"최적화",Checklist!$G:$G,"N"),COUNTIFS(Checklist!$A:$A,$A42,Checklist!$B:$B,$B42,Checklist!$C:$C,$C42,Checklist!$E:$E,"최적화",Checklist!$G:$G,"N"))=0),0.7+0.3*IF(H42=0,0,G42/H42),0.4+0.3*IF(F42=0,0,E42/F42)))) -> 1
A43: 자동화 및 통합 | C43: 정책 통합 | D43: =IF($B43="",COUNTIFS(Checklist!$A:$A,$A43,Checklist!$C:$C,$C43,Checklist!$E:$E,"초기",Checklist!$G:$G,"N"),COUNTIFS(Checklist!$A:$A,$A43,Checklist!$B:$B,$B43,Checklist!$C:$C,$C43,Checklist!$E:$E,"초기",Checklist!$G:$G,"N")) -> 0 | E43: =IF($B43="",COUNTIFS(Checklist!$A:$A,$A43,Checklist!$C:$C,$C43,Checklist!$E:$E,"향상",Checklist!$G:$G,"Y"),COUNTIFS(Checklist!$A:$A,$A43,Checklist!$B:$B,$B43,Checklist!$C:$C,$C43,Checklist!$E:$E,"향상",Checklist!$G:$G,"Y")) -> 2 | F43: =IF($B43="",COUNTIFS(Checklist!$A:$A,$A43,Checklist!$C:$C,$C43,Checklist!$E:$E,"향상",Checklist!$H:$H,"<>"),COUNTIFS(Checklist!$A:$A,$A43,Checklist!$B:$B,$B43,Checklist!$C:$C,$C43,Checklist!$E:$E,"향상",Checklist!$H:$H,"<>")) -> 2 | G43: =IF($B43="",COUNTIFS(Checklist!$A:$A,$A43,Checklist!$C:$C,$C43,Checklist!$E:$E,"최적화",Checklist!$G:$G,"Y"),COUNTIFS(Checklist!$A:$A,$A43,Checklist!$B:$B,$B43,Checklist!$C:$C,$C43,Checklist!$E:$E,"최적화",Checklist!$G:$G,"Y")) -> 4 | H43: =IF($B43="",COUNTIFS(Checklist!$A:$A,$A43,Checklist!$C:$C,$C43,Checklist!$E:$E,"최적화",Checklist!$H:$H,"<>"),COUNTIFS(Checklist!$A:$A,$A43,Checklist!$B:$B,$B43,Checklist!$C:$C,$C43,Checklist!$E:$E,"최적화",Checklist!$H:$H,"<>")) -> 4 | I43: =IF(D43>0,0,IF(AND(F43=0,H43=0),0.4,IF(AND(F43>0,IF($B43="",COUNTIFS(Checklist!$A:$A,$A43,Checklist!$C:$C,$C43,Checklist!$E:$E,"향상",Checklist!$G:$G,"N"),COUNTIFS(Checklist!$A:$A,$A43,Checklist!$B:$B,$B43,Checklist!$C:$C,$C43,Checklist!$E:$E,"향상",Checklist!$G:$G,"N"))=0,H43>0,IF($B43="",COUNTIFS(Checklist!$A:$A,$A43,Checklist!$C:$C,$C43,Checklist!$E:$E,"최적화",Checklist!$G:$G,"N"),COUNTIFS(Checklist!$A:$A,$A43,Checklist!$B:$B,$B43,Checklist!$C:$C,$C43,Checklist!$E:$E,"최적화",Checklist!$G:$G,"N"))=0),0.7+0.3*IF(H43=0,0,G43/H43),0.4+0.3*IF(F43=0,0,E43/F43)))) -> 1
A44: 자동화 및 통합 | C44: 중요 프로세스 자동화 | D44: =IF($B44="",COUNTIFS(Checklist!$A:$A,$A44,Checklist!$C:$C,$C44,Checklist!$E:$E,"초기",Checklist!$G:$G,"N"),COUNTIFS(Checklist!$A:$A,$A44,Checklist!$B:$B,$B44,Checklist!$C:$C,$C44,Checklist!$E:$E,"초기",Checklist!$G:$G,"N")) -> 0 | E44: =IF($B44="",COUNTIFS(Checklist!$A:$A,$A44,Checklist!$C:$C,$C44,Checklist!$E:$E,"향상",Checklist!$G:$G,"Y"),COUNTIFS(Checklist!$A:$A,$A44,Checklist!$B:$B,$B44,Checklist!$C:$C,$C44,Checklist!$E:$E,"향상",Checklist!$G:$G,"Y")) -> 2 | F44: =IF($B44="",COUNTIFS(Checklist!$A:$A,$A44,Checklist!$C:$C,$C44,Checklist!$E:$E,"향상",Checklist!$H:$H,"<>"),COUNTIFS(Checklist!$A:$A,$A44,Checklist!$B:$B,$B44,Checklist!$C:$C,$C44,Checklist!$E:$E,"향상",Checklist!$H:$H,"<>")) -> 2 | G44: =IF($B44="",COUNTIFS(Checklist!$A:$A,$A44,Checklist!$C:$C,$C44,Checklist!$E:$E,"최적화",Checklist!$G:$G,"Y"),COUNTIFS(Checklist!$A:$A,$A44,Checklist!$B:$B,$B44,Checklist!$C:$C,$C44,Checklist!$E:$E,"최적화",Checklist!$G:$G,"Y")) -> 4 | H44: =IF($B44="",COUNTIFS(Checklist!$A:$A,$A44,Checklist!$C:$C,$C44,Checklist!$E:$E,"최적화",Checklist!$H:$H,"<>"),COUNTIFS(Checklist!$A:$A,$A44,Checklist!$B:$B,$B44,Checklist!$C:$C,$C44,Checklist!$E:$E,"최적화",Checklist!$H:$H,"<>")) -> 4 | I44: =IF(D44>0,0,IF(AND(F44=0,H44=0),0.4,IF(AND(F44>0,IF($B44="",COUNTIFS(Checklist!$A:$A,$A44,Checklist!$C:$C,$C44,Checklist!$E:$E,"향상",Checklist!$G:$G,"N"),COUNTIFS(Checklist!$A:$A,$A44,Checklist!$B:$B,$B44,Checklist!$C:$C,$C44,Checklist!$E:$E,"향상",Checklist!$G:$G,"N"))=0,H44>0,IF($B44="",COUNTIFS(Checklist!$A:$A,$A44,Checklist!$C:$C,$C44,Checklist!$E:$E,"최적화",Checklist!$G:$G,"N"),COUNTIFS(Checklist!$A:$A,$A44,Checklist!$B:$B,$B44,Checklist!$C:$C,$C44,Checklist!$E:$E,"최적화",Checklist!$G:$G,"N"))=0),0.7+0.3*IF(H44=0,0,G44/H44),0.4+0.3*IF(F44=0,0,E44/F44)))) -> 1
A45: 자동화 및 통합 | C45: 인공지능 | D45: =IF($B45="",COUNTIFS(Checklist!$A:$A,$A45,Checklist!$C:$C,$C45,Checklist!$E:$E,"초기",Checklist!$G:$G,"N"),COUNTIFS(Checklist!$A:$A,$A45,Checklist!$B:$B,$B45,Checklist!$C:$C,$C45,Checklist!$E:$E,"초기",Checklist!$G:$G,"N")) -> 0 | E45: =IF($B45="",COUNTIFS(Checklist!$A:$A,$A45,Checklist!$C:$C,$C45,Checklist!$E:$E,"향상",Checklist!$G:$G,"Y"),COUNTIFS(Checklist!$A:$A,$A45,Checklist!$B:$B,$B45,Checklist!$C:$C,$C45,Checklist!$E:$E,"향상",Checklist!$G:$G,"Y")) -> 1 | F45: =IF($B45="",COUNTIFS(Checklist!$A:$A,$A45,Checklist!$C:$C,$C45,Checklist!$E:$E,"향상",Checklist!$H:$H,"<>"),COUNTIFS(Checklist!$A:$A,$A45,Checklist!$B:$B,$B45,Checklist!$C:$C,$C45,Checklist!$E:$E,"향상",Checklist!$H:$H,"<>")) -> 2 | G45: =IF($B45="",COUNTIFS(Checklist!$A:$A,$A45,Checklist!$C:$C,$C45,Checklist!$E:$E,"최적화",Checklist!$G:$G,"Y"),COUNTIFS(Checklist!$A:$A,$A45,Checklist!$B:$B,$B45,Checklist!$C:$C,$C45,Checklist!$E:$E,"최적화",Checklist!$G:$G,"Y")) -> 3 | H45: =IF($B45="",COUNTIFS(Checklist!$A:$A,$A45,Checklist!$C:$C,$C45,Checklist!$E:$E,"최적화",Checklist!$H:$H,"<>"),COUNTIFS(Checklist!$A:$A,$A45,Checklist!$B:$B,$B45,Checklist!$C:$C,$C45,Checklist!$E:$E,"최적화",Checklist!$H:$H,"<>")) -> 3 | I45: =IF(D45>0,0,IF(AND(F45=0,H45=0),0.4,IF(AND(F45>0,IF($B45="",COUNTIFS(Checklist!$A:$A,$A45,Checklist!$C:$C,$C45,Checklist!$E:$E,"향상",Checklist!$G:$G,"N"),COUNTIFS(Checklist!$A:$A,$A45,Checklist!$B:$B,$B45,Checklist!$C:$C,$C45,Checklist!$E:$E,"향상",Checklist!$G:$G,"N"))=0,H45>0,IF($B45="",COUNTIFS(Checklist!$A:$A,$A45,Checklist!$C:$C,$C45,Checklist!$E:$E,"최적화",Checklist!$G:$G,"N"),COUNTIFS(Checklist!$A:$A,$A45,Checklist!$B:$B,$B45,Checklist!$C:$C,$C45,Checklist!$E:$E,"최적화",Checklist!$G:$G,"N"))=0),0.7+0.3*IF(H45=0,0,G45/H45),0.4+0.3*IF(F45=0,0,E45/F45)))) -> 0.55
A46: 자동화 및 통합 | C46: 보안 통합, 자동화 및 대응(SOAR) | D46: =IF($B46="",COUNTIFS(Checklist!$A:$A,$A46,Checklist!$C:$C,$C46,Checklist!$E:$E,"초기",Checklist!$G:$G,"N"),COUNTIFS(Checklist!$A:$A,$A46,Checklist!$B:$B,$B46,Checklist!$C:$C,$C46,Checklist!$E:$E,"초기",Checklist!$G:$G,"N")) -> 0 | E46: =IF($B46="",COUNTIFS(Checklist!$A:$A,$A46,Checklist!$C:$C,$C46,Checklist!$E:$E,"향상",Checklist!$G:$G,"Y"),COUNTIFS(Checklist!$A:$A,$A46,Checklist!$B:$B,$B46,Checklist!$C:$C,$C46,Checklist!$E:$E,"향상",Checklist!$G:$G,"Y")) -> 3 | F46: =IF($B46="",COUNTIFS(Checklist!$A:$A,$A46,Checklist!$C:$C,$C46,Checklist!$E:$E,"향상",Checklist!$H:$H,"<>"),COUNTIFS(Checklist!$A:$A,$A46,Checklist!$B:$B,$B46,Checklist!$C:$C,$C46,Checklist!$E:$E,"향상",Checklist!$H:$H,"<>")) -> 3 | G46: =IF($B46="",COUNTIFS(Checklist!$A:$A,$A46,Checklist!$C:$C,$C46,Checklist!$E:$E,"최적화",Checklist!$G:$G,"Y"),COUNTIFS(Checklist!$A:$A,$A46,Checklist!$B:$B,$B46,Checklist!$C:$C,$C46,Checklist!$E:$E,"최적화",Checklist!$G:$G,"Y")) -> 4 | H46: =IF($B46="",COUNTIFS(Checklist!$A:$A,$A46,Checklist!$C:$C,$C46,Checklist!$E:$E,"최적화",Checklist!$H:$H,"<>"),COUNTIFS(Checklist!$A:$A,$A46,Checklist!$B:$B,$B46,Checklist!$C:$C,$C46,Checklist!$E:$E,"최적화",Checklist!$H:$H,"<>")) -> 4 | I46: =IF(D46>0,0,IF(AND(F46=0,H46=0),0.4,IF(AND(F46>0,IF($B46="",COUNTIFS(Checklist!$A:$A,$A46,Checklist!$C:$C,$C46,Checklist!$E:$E,"향상",Checklist!$G:$G,"N"),COUNTIFS(Checklist!$A:$A,$A46,Checklist!$B:$B,$B46,Checklist!$C:$C,$C46,Checklist!$E:$E,"향상",Checklist!$G:$G,"N"))=0,H46>0,IF($B46="",COUNTIFS(Checklist!$A:$A,$A46,Checklist!$C:$C,$C46,Checklist!$E:$E,"최적화",Checklist!$G:$G,"N"),COUNTIFS(Checklist!$A:$A,$A46,Checklist!$B:$B,$B46,Checklist!$C:$C,$C46,Checklist!$E:$E,"최적화",Checklist!$G:$G,"N"))=0),0.7+0.3*IF(H46=0,0,G46/H46),0.4+0.3*IF(F46=0,0,E46/F46)))) -> 1
A47: 자동화 및 통합 | C47: 데이터 교환 표준화 | D47: =IF($B47="",COUNTIFS(Checklist!$A:$A,$A47,Checklist!$C:$C,$C47,Checklist!$E:$E,"초기",Checklist!$G:$G,"N"),COUNTIFS(Checklist!$A:$A,$A47,Checklist!$B:$B,$B47,Checklist!$C:$C,$C47,Checklist!$E:$E,"초기",Checklist!$G:$G,"N")) -> 0 | E47: =IF($B47="",COUNTIFS(Checklist!$A:$A,$A47,Checklist!$C:$C,$C47,Checklist!$E:$E,"향상",Checklist!$G:$G,"Y"),COUNTIFS(Checklist!$A:$A,$A47,Checklist!$B:$B,$B47,Checklist!$C:$C,$C47,Checklist!$E:$E,"향상",Checklist!$G:$G,"Y")) -> 3 | F47: =IF($B47="",COUNTIFS(Checklist!$A:$A,$A47,Checklist!$C:$C,$C47,Checklist!$E:$E,"향상",Checklist!$H:$H,"<>"),COUNTIFS(Checklist!$A:$A,$A47,Checklist!$B:$B,$B47,Checklist!$C:$C,$C47,Checklist!$E:$E,"향상",Checklist!$H:$H,"<>")) -> 3 | G47: =IF($B47="",COUNTIFS(Checklist!$A:$A,$A47,Checklist!$C:$C,$C47,Checklist!$E:$E,"최적화",Checklist!$G:$G,"Y"),COUNTIFS(Checklist!$A:$A,$A47,Checklist!$B:$B,$B47,Checklist!$C:$C,$C47,Checklist!$E:$E,"최적화",Checklist!$G:$G,"Y")) -> 4 | H47: =IF($B47="",COUNTIFS(Checklist!$A:$A,$A47,Checklist!$C:$C,$C47,Checklist!$E:$E,"최적화",Checklist!$H:$H,"<>"),COUNTIFS(Checklist!$A:$A,$A47,Checklist!$B:$B,$B47,Checklist!$C:$C,$C47,Checklist!$E:$E,"최적화",Checklist!$H:$H,"<>")) -> 4 | I47: =IF(D47>0,0,IF(AND(F47=0,H47=0),0.4,IF(AND(F47>0,IF($B47="",COUNTIFS(Checklist!$A:$A,$A47,Checklist!$C:$C,$C47,Checklist!$E:$E,"향상",Checklist!$G:$G,"N"),COUNTIFS(Checklist!$A:$A,$A47,Checklist!$B:$B,$B47,Checklist!$C:$C,$C47,Checklist!$E:$E,"향상",Checklist!$G:$G,"N"))=0,H47>0,IF($B47="",COUNTIFS(Checklist!$A:$A,$A47,Checklist!$C:$C,$C47,Checklist!$E:$E,"최적화",Checklist!$G:$G,"N"),COUNTIFS(Checklist!$A:$A,$A47,Checklist!$B:$B,$B47,Checklist!$C:$C,$C47,Checklist!$E:$E,"최적화",Checklist!$G:$G,"N"))=0),0.7+0.3*IF(H47=0,0,G47/H47),0.4+0.3*IF(F47=0,0,E47/F47)))) -> 1
A48: 자동화 및 통합 | C48: 보안 운영 조정 및 사고 대응 | D48: =IF($B48="",COUNTIFS(Checklist!$A:$A,$A48,Checklist!$C:$C,$C48,Checklist!$E:$E,"초기",Checklist!$G:$G,"N"),COUNTIFS(Checklist!$A:$A,$A48,Checklist!$B:$B,$B48,Checklist!$C:$C,$C48,Checklist!$E:$E,"초기",Checklist!$G:$G,"N")) -> 0 | E48: =IF($B48="",COUNTIFS(Checklist!$A:$A,$A48,Checklist!$C:$C,$C48,Checklist!$E:$E,"향상",Checklist!$G:$G,"Y"),COUNTIFS(Checklist!$A:$A,$A48,Checklist!$B:$B,$B48,Checklist!$C:$C,$C48,Checklist!$E:$E,"향상",Checklist!$G:$G,"Y")) -> 2 | F48: =IF($B48="",COUNTIFS(Checklist!$A:$A,$A48,Checklist!$C:$C,$C48,Checklist!$E:$E,"향상",Checklist!$H:$H,"<>"),COUNTIFS(Checklist!$A:$A,$A48,Checklist!$B:$B,$B48,Checklist!$C:$C,$C48,Checklist!$E:$E,"향상",Checklist!$H:$H,"<>")) -> 4 | G48: =IF($B48="",COUNTIFS(Checklist!$A:$A,$A48,Checklist!$C:$C,$C48,Checklist!$E:$E,"최적화",Checklist!$G:$G,"Y"),COUNTIFS(Checklist!$A:$A,$A48,Checklist!$B:$B,$B48,Checklist!$C:$C,$C48,Checklist!$E:$E,"최적화",Checklist!$G:$G,"Y")) -> 5 | H48: =IF($B48="",COUNTIFS(Checklist!$A:$A,$A48,Checklist!$C:$C,$C48,Checklist!$E:$E,"최적화",Checklist!$H:$H,"<>"),COUNTIFS(Checklist!$A:$A,$A48,Checklist!$B:$B,$B48,Checklist!$C:$C,$C48,Checklist!$E:$E,"최적화",Checklist!$H:$H,"<>")) -> 6 | I48: =IF(D48>0,0,IF(AND(F48=0,H48=0),0.4,IF(AND(F48>0,IF($B48="",COUNTIFS(Checklist!$A:$A,$A48,Checklist!$C:$C,$C48,Checklist!$E:$E,"향상",Checklist!$G:$G,"N"),COUNTIFS(Checklist!$A:$A,$A48,Checklist!$B:$B,$B48,Checklist!$C:$C,$C48,Checklist!$E:$E,"향상",Checklist!$G:$G,"N"))=0,H48>0,IF($B48="",COUNTIFS(Checklist!$A:$A,$A48,Checklist!$C:$C,$C48,Checklist!$E:$E,"최적화",Checklist!$G:$G,"N"),COUNTIFS(Checklist!$A:$A,$A48,Checklist!$B:$B,$B48,Checklist!$C:$C,$C48,Checklist!$E:$E,"최적화",Checklist!$G:$G,"N"))=0),0.7+0.3*IF(H48=0,0,G48/H48),0.4+0.3*IF(F48=0,0,E48/F48)))) -> 0.55

Sheet FunctionSummary
A1: Pillar7 | B1: Function | C1: FuncScore
A2: 신원 | B2: 식별자 관리 | C2: =IFERROR(AVERAGEIFS(SubFunctionSummary!$I:$I,SubFunctionSummary!$A:$A,$A2,SubFunctionSummary!$B:$B,$B2),"") -> 0.2
A3: 신원 | B3: 인증 | C3: =IFERROR(AVERAGEIFS(SubFunctionSummary!$I:$I,SubFunctionSummary!$A:$A,$A3,SubFunctionSummary!$B:$B,$B3),"") -> 0.5
A4: 신원 | B4: 위험도 평가 | C4: =IFERROR(AVERAGEIFS(SubFunctionSummary!$I:$I,SubFunctionSummary!$A:$A,$A4,SubFunctionSummary!$B:$B,$B4),"") -> 1
A5: 신원 | B5: 접근 관리 | C5: =IFERROR(AVERAGEIFS(SubFunctionSummary!$I:$I,SubFunctionSummary!$A:$A,$A5,SubFunctionSummary!$B:$B,$B5),"") -> 1
A6: 기기 및 엔드포인트 | B6: 정책 준수 모니터링 | C6: =IFERROR(AVERAGEIFS(SubFunctionSummary!$I:$I,SubFunctionSummary!$A:$A,$A6,SubFunctionSummary!$B:$B,$B6),"") -> 1
A7: 기기 및 엔드포인트 | B7: 데이터 접근제어 | C7: =IFERROR(AVERAGEIFS(SubFunctionSummary!$I:$I,SubFunctionSummary!$A:$A,$A7,SubFunctionSummary!$B:$B,$B7),"") -> 1
A8: 기기 및 엔드포인트 | B8: 자산 관리 | C8: =IFERROR(AVERAGEIFS(SubFunctionSummary!$I:$I,SubFunctionSummary!$A:$A,$A8,SubFunctionSummary!$B:$B,$B8),"") -> 1
A9: 기기 및 엔드포인트 | B9: 기기 위협 보호 | C9: =IFERROR(AVERAGEIFS(SubFunctionSummary!$I:$I,SubFunctionSummary!$A:$A,$A9,SubFunctionSummary!$B:$B,$B9),"") -> 1
A10: 네트워크 | B10: 네트워크 세분화 | C10: =IFERROR(AVERAGEIFS(SubFunctionSummary!$I:$I,SubFunctionSummary!$A:$A,$A10,SubFunctionSummary!$B:$B,$B10),"") -> 1
A11: 네트워크 | B11: 위협 대응 | C11: =IFERROR(AVERAGEIFS(SubFunctionSummary!$I:$I,SubFunctionSummary!$A:$A,$A11,SubFunctionSummary!$B:$B,$B11),"") -> 1
A12: 네트워크 | B12: 트래픽 암호화 | C12: =IFERROR(AVERAGEIFS(SubFunctionSummary!$I:$I,SubFunctionSummary!$A:$A,$A12,SubFunctionSummary!$B:$B,$B12),"") -> 1
A13: 네트워크 | B13: 트래픽 관리 | C13: =IFERROR(AVERAGEIFS(SubFunctionSummary!$I:$I,SubFunctionSummary!$A:$A,$A13,SubFunctionSummary!$B:$B,$B13),"") -> 1
... A24: 데이터 | B24: 데이터 손실 방지 | C24: =IFERROR(AVERAGEIFS(SubFunctionSummary!$I:$I,SubFunctionSummary!$A:$A,$A24,SubFunctionSummary!$B:$B,$B24),"") -> 1

Sheet PillarSummary
A1: Pillar7 | B1: FuncScore | C1: Weight | D1: PillarScore
A2: 신원 | B2: =IFERROR(AVERAGEIFS(FunctionSummary!$C:$C,FunctionSummary!$A:$A,$A2),"") -> 0.675 | C2: 0.2 | D2: =IF(B2="","",B2*C2) -> 0.135
A3: 기기 및 엔드포인트 | B3: =IFERROR(AVERAGEIFS(FunctionSummary!$C:$C,FunctionSummary!$A:$A,$A3),"") -> 1 | C3: 0.15 | D3: =IF(B3="","",B3*C3) -> 0.15
A4: 네트워크 | B4: =IFERROR(AVERAGEIFS(FunctionSummary!$C:$C,FunctionSummary!$A:$A,$A4),"") -> 1 | C4: 0.15 | D4: =IF(B4="","",B4*C4) -> 0.15
A5: 애플리케이션 및 워크로드 | B5: =IFERROR(AVERAGEIFS(FunctionSummary!$C:$C,FunctionSummary!$A:$A,$A5),"") -> 1 | C5: 0.13 | D5: =IF(B5="","",B5*C5) -> 0.13
A6: 데이터 | B6: =IFERROR(AVERAGEIFS(FunctionSummary!$C:$C,FunctionSummary!$A:$A,$A6),"") -> 1 | C6: 0.15 | D6: =IF(B6="","",B6*C6) -> 0.15
A7: 가시성 및 분석 | B7: =IFERROR(AVERAGEIFS(SubFunctionSummary!$I:$I,SubFunctionSummary!$A:$A,$A7),"") -> 1 | C7: 0.12 | D7: =IF(B7="","",B7*C7) -> 0.12
A8: 자동화 및 통합 | B8: =IFERROR(AVERAGEIFS(SubFunctionSummary!$I:$I,SubFunctionSummary!$A:$A,$A8),"") -> 0.85 | C8: 0.1 | D8: =IF(B8="","",B8*C8) -> 0.085
A9: Total | B9: =SUM(D2:D8) -> 0.92

Sheet AssetStart

Sheet Asset
A1: 자산가치 점수 | K1: 최종 자산 중요도 [CIA*0.6] + [자산가치*0.4] | L1: =SUM(I39*0.6,D99*0.4) -> 0.87726776
A3: 평가 요인 (가중치) | B3: 세부 영향요인 | C3: 정의 (문서 기반) | D3: 가치 영향(부정/긍정) | E3: 문서 내 참조표 | F3: 점수(1~5) | G3: 정규화(부호 반영, 0.2~1.0) | H3: 가중치 | I3: 반영값(정규화×가중치)
A4: 데이터 특성(0.35) | B4: 우수성 | C4: 유사 데이터 대비 품질·차별성의 우위 정도 | D4: + | E4: [표 3] | F4: 5 | G4: =IF(F4="","",IF(D4="+",0.2+(F4-1)*0.2,1.2-(0.2+(F4-1)*0.2))) -> 1 | H4: 0.35 | I4: =IF(G4="","",G4*H4) -> 0.35
B5: 모방난이도 | C5: 수집·가공 난이도와 접근성으로 인한 모방의 어려움 정도 | D5: + | E5: [표 3] | F5: 5 | G5: =IF(F5="","",IF(D5="+",0.2+(F5-1)*0.2,1.2-(0.2+(F5-1)*0.2))) -> 1 | H5: 0.35 | I5: =IF(G5="","",G5*H5) -> 0.35
B6: 지속가능성 | C6: 데이터가 주기적으로 지속 생산·공급될 수 있는 정도 | D6: + | E6: [표 3] | F6: 5 | G6: =IF(F6="","",IF(D6="+",0.2+(F6-1)*0.2,1.2-(0.2+(F6-1)*0.2))) -> 1 | H6: 0.35 | I6: =IF(G6="","",G6*H6) -> 0.35
B7: 경쟁 강도 | C7: 동일·유사 데이터와의 경쟁 압력 수준 | D7: - | E7: [표 3] | F7: 5 | G7: =IF(F7="","",IF(D7="+",0.2+(F7-1)*0.2,1.2-(0.2+(F7-1)*0.2))) -> 0.2 | H7: 0.35 | I7: =IF(G7="","",G7*H7) -> 0.07
B8: 대체가능성 | C8: 대체 가능한 유사 데이터의 존재 가능성 | D8: - | E8: [표 3] | F8: 5 | G8: =IF(F8="","",IF(D8="+",0.2+(F8-1)*0.2,1.2-(0.2+(F8-1)*0.2))) -> 0.2 | H8: 0.35 | I8: =IF(G8="","",G8*H8) -> 0.07
B9: 활용성 및 파급성 | C9: 도입 시 내부/타산업 확산 및 매출 파급 가능성 | D9: + | E9: [표 3] | F9: 5 | G9: =IF(F9="","",IF(D9="+",0.2+(F9-1)*0.2,1.2-(0.2+(F9-1)*0.2))) -> 1 | H9: 0.35 | I9: =IF(G9="","",G9*H9) -> 0.35
B10: 최신성 | C10: 데이터가 최신 상태를 유지하는 정도 | D10: + | E10: [표 3] | F10: 5 | G10: =IF(F10="","",IF(D10="+",0.2+(F10-1)*0.2,1.2-(0.2+(F10-1)*0.2))) -> 1 | H10: 0.35 | I10: =IF(G10="","",G10*H10) -> 0.35
B11: 정확성 | C11: 목적 대비 사실성·정확성 수준 | D11: + | E11: [표 3] | F11: 5 | G11: =IF(F11="","",IF(D11="+",0.2+(F11-1)*0.2,1.2-(0.2+(F11-1)*0.2))) -> 1 | H11: 0.35 | I11: =IF(G11="","",G11*H11) -> 0.35
B12: 성숙도 | C12: 정제·가공 등 처리 진행 수준 | D12: + | E12: [표 3] | F12: 5 | G12: =IF(F12="","",IF(D12="+",0.2+(F12-1)*0.2,1.2-(0.2+(F12-1)*0.2))) -> 1 | H12: 0.35 | I12: =IF(G12="","",G12*H12) -> 0.35
B13: 완전성 | C13: 필수 정보 누락 없이 충실히 포함된 정도 | D13: + | E13: [표 3] | F13: 5 | G13: =IF(F13="","",IF(D13="+",0.2+(F13-1)*0.2,1.2-(0.2+(F13-1)*0.2))) -> 1 | H13: 0.35 | I13: =IF(G13="","",G13*H13) -> 0.35
B14: 혁신성 | C14: 기존 것을 새롭게 바꿀 수 있는 혁신의 정도 | D14: + | E14: [표 3] | F14: 5 | G14: =IF(F14="","",IF(D14="+",0.2+(F14-1)*0.2,1.2-(0.2+(F14-1)*0.2))) -> 1 | H14: 0.35 | I14: =IF(G14="","",G14*H14) -> 0.35
B15: 확장성 | C15: 환경 변화에 따른 서비스 확장 적합성 | D15: + | E15: [표 3] | F15: 5 | G15: =IF(F15="","",IF(D15="+",0.2+(F15-1)*0.2,1.2-(0.2+(F15-1)*0.2))) -> 1 | H15: 0.35 | I15: =IF(G15="","",G15*H15) -> 0.35
B16: 일관성 | C16: 정의된 규칙·형식을 일관되게 따르는 정도 | D16: + | E16: [표 3] | F16: 5 | G16: =IF(F16="","",IF(D16="+",0.2+(F16-1)*0.2,1.2-(0.2+(F16-1)*0.2))) -> 1 | H16: 0.35 | I16: =IF(G16="","",G16*H16) -> 0.35
... B21: 인지도 | C21: 대외 인지도·명성 수준 | D21: + | E21: [표 3] | F21: 5 | G21: =IF(F21="","",IF(D21="+",0.2+(F21-1)*0.2,1.2-(0.2+(F21-1)*0.2))) -> 1 | H21: 0.35 | I21: =IF(G21="","",G21*H21) -> 0.35
A22: 법적 특성(0.30) | B22: 법적 안정성 | C22: 수집·이용·보호조치 등 법요건 부합 정도 | D22: + | E22: [표 5] | F22: 5 | G22: =IF(F22="","",IF(D22="+",0.2+(F22-1)*0.2,1.2-(0.2+(F22-1)*0.2))) -> 1 | H22: 0.3 | I22: =IF(G22="","",G22*H22) -> 0.3
A23: 시장성(0.20) | B23: 시장진입 가능성 | C23: 서비스가 시장에 원활히 진입할 수 있는 정도 | D23: + | E23: [표 6] | F23: 5 | G23: =IF(F23="","",IF(D23="+",0.2+(F23-1)*0.2,1.2-(0.2+(F23-1)*0.2))) -> 1 | H23: 0.2 | I23: =IF(G23="","",G23*H23) -> 0.2
B24: 시장경쟁강도 | C24: 목표 시장 내 경쟁 강도가 사업화에 미치는 영향 | D24: - | E24: [표 6] | F24: 5 | G24: =IF(F24="","",IF(D24="+",0.2+(F24-1)*0.2,1.2-(0.2+(F24-1)*0.2))) -> 0.2 | H24: 0.2 | I24: =IF(G24="","",G24*H24) -> 0.04
B25: 시장성장성 | C25: 출시 후 성장 가능성 | D25: + | E25: [표 6] | F25: 5 | G25: =IF(F25="","",IF(D25="+",0.2+(F25-1)*0.2,1.2-(0.2+(F25-1)*0.2))) -> 1 | H25: 0.2 | I25: =IF(G25="","",G25*H25) -> 0.2
B26: 수요민감도 | C26: 수요 변화에 대한 민감도(변동성) | D26: - | E26: [표 6] | F26: 5 | G26: =IF(F26="","",IF(D26="+",0.2+(F26-1)*0.2,1.2-(0.2+(F26-1)*0.2))) -> 0.2 | H26: 0.2 | I26: =IF(G26="","",G26*H26) -> 0.04
B27: 서비스(제품) 사용성 | C27: 데이터 활용 시 사용자 편의성 향상 정도 | D27: + | E27: [표 6] | F27: 5 | G27: =IF(F27="","",IF(D27="+",0.2+(F27-1)*0.2,1.2-(0.2+(F27-1)*0.2))) -> 1 | H27: 0.2 | I27: =IF(G27="","",G27*H27) -> 0.2
